Workbook

Sheet لوحة الإشراف العامة للقسم
A1: لوحة المتابعة الإشرافية العامة للتعليم عن بعد - قسم الرياضيات (النسخة المبسطة المحدثة)
A3: فلتر الأسبوع (1 - 17): | C3: جميع الأسابيع | D3: فلتر المجمع التعليمي: | F3: جميع المجمعات
A5: اسم المشرف التربوي | B5: إجمالي المعلمين (تميز/تحسين) | C5: المعلمون المتميزون | D5: الملاحظات وفرص التطوير | E5: الملاحظات المحلولة | F5: الملاحظات المستمرة | G5: نسبة الإغلاق | H5: حالة الإنجاز
A6: السيد سالم | B6: =IF(AND($C$3="جميع الأسابيع",$F$3="جميع المجمعات"), 'السيد سالم'!D3, IF($C$3="جميع الأسابيع", COUNTIF('السيد سالم'!$C$13:$C$32,$F$3)+COUNTIF('السيد سالم'!$B$35:$B$70,$F$3), IF($F$3="جميع المجمعات", COUNTIF('السيد سالم'!$A$13:$A$32,$C$3)+COUNTIF('السيد سالم'!$A$35:$A$70,$C$3), COUNTIFS('السيد سالم'!$A$13:$A$32,$C$3,'السيد سالم'!$C$13:$C$32,$F$3)+COUNTIFS('السيد سالم'!$A$35:$A$70,$C$3,'السيد سالم'!$B$35:$B$70,$F$3)))) -> 19 | C6: =IF(AND($C$3="جميع الأسابيع",$F$3="جميع المجمعات"), 'السيد سالم'!D4, IF($C$3="جميع الأسابيع", COUNTIF('السيد سالم'!$C$13:$C$32,$F$3), IF($F$3="جميع المجمعات", COUNTIF('السيد سالم'!$A$13:$A$32,$C$3), COUNTIFS('السيد سالم'!$A$13:$A$32,$C$3,'السيد سالم'!$C$13:$C$32,$F$3)))) -> 11 | D6: =IF(AND($C$3="جميع الأسابيع",$F$3="جميع المجمعات"), 'السيد سالم'!D5, IF($C$3="جميع الأسابيع", COUNTIF('السيد سالم'!$B$35:$B$70,$F$3), IF($F$3="جميع المجمعات", COUNTIF('السيد سالم'!$A$35:$A$70,$C$3), COUNTIFS('السيد سالم'!$A$35:$A$70,$C$3,'السيد سالم'!$B$35:$B$70,$F$3)))) -> 8 | E6: =IF(AND($C$3="جميع الأسابيع",$F$3="جميع المجمعات"), 'السيد سالم'!D6, IF($C$3="جميع الأسابيع", COUNTIFS('السيد سالم'!$B$35:$B$70,$F$3,'السيد سالم'!$G$35:$G$70,"تم الحل"), IF($F$3="جميع المجمعات", COUNTIFS('السيد سالم'!$A$35:$A$70,$C$3,'السيد سالم'!$G$35:$G$70,"تم الحل"), COUNTIFS('السيد سالم'!$A$35:$A$70,$C$3,'السيد سالم'!$B$35:$B$70,$F$3,'السيد سالم'!$G$35:$G$70,"تم الحل")))) -> 5 | F6: =IF(AND($C$3="جميع الأسابيع",$F$3="جميع المجمعات"), 'السيد سالم'!D7, IF($C$3="جميع الأسابيع", COUNTIFS('السيد سالم'!$B$35:$B$70,$F$3,'السيد سالم'!$G$35:$G$70,"مستمرة"), IF($F$3="جميع المجمعات", COUNTIFS('السيد سالم'!$A$35:$A$70,$C$3,'السيد سالم'!$G$35:$G$70,"مستمرة"), COUNTIFS('السيد سالم'!$A$35:$A$70,$C$3,'السيد سالم'!$B$35:$B$70,$F$3,'السيد سالم'!$G$35:$G$70,"مستمرة")))) -> 3 | G6: =IFERROR(E6/(E6+F6), 0) -> 0.625 | H6: =IF(B6=0, "لا توجد بيانات", IF(F6=0, "مكتمل ومغلق", "قيد المتابعة")) -> قيد المتابعة
A7: محمد السويركي | B7: =IF(AND($C$3="جميع الأسابيع",$F$3="جميع المجمعات"), 'محمد السويركي'!D3, IF($C$3="جميع الأسابيع", COUNTIF('محمد السويركي'!$C$13:$C$32,$F$3)+COUNTIF('محمد السويركي'!$B$35:$B$70,$F$3), IF($F$3="جميع المجمعات", COUNTIF('محمد السويركي'!$A$13:$A$32,$C$3)+COUNTIF('محمد السويركي'!$A$35:$A$70,$C$3), COUNTIFS('محمد السويركي'!$A$13:$A$32,$C$3,'محمد السويركي'!$C$13:$C$32,$F$3)+COUNTIFS('محمد السويركي'!$A$35:$A$70,$C$3,'محمد السويركي'!$B$35:$B$70,$F$3)))) -> 19 | C7: =IF(AND($C$3="جميع الأسابيع",$F$3="جميع المجمعات"), 'محمد السويركي'!D4, IF($C$3="جميع الأسابيع", COUNTIF('محمد السويركي'!$C$13:$C$32,$F$3), IF($F$3="جميع المجمعات", COUNTIF('محمد السويركي'!$A$13:$A$32,$C$3), COUNTIFS('محمد السويركي'!$A$13:$A$32,$C$3,'محمد السويركي'!$C$13:$C$32,$F$3)))) -> 17 | D7: =IF(AND($C$3="جميع الأسابيع",$F$3="جميع المجمعات"), 'محمد السويركي'!D5, IF($C$3="جميع الأسابيع", COUNTIF('محمد السويركي'!$B$35:$B$70,$F$3), IF($F$3="جميع المجمعات", COUNTIF('محمد السويركي'!$A$35:$A$70,$C$3), COUNTIFS('محمد السويركي'!$A$35:$A$70,$C$3,'محمد السويركي'!$B$35:$B$70,$F$3)))) -> 2 | E7: =IF(AND($C$3="جميع الأسابيع",$F$3="جميع المجمعات"), 'محمد السويركي'!D6, IF($C$3="جميع الأسابيع", COUNTIFS('محمد السويركي'!$B$35:$B$70,$F$3,'محمد السويركي'!$G$35:$G$70,"تم الحل"), IF($F$3="جميع المجمعات", COUNTIFS('محمد السويركي'!$A$35:$A$70,$C$3,'محمد السويركي'!$G$35:$G$70,"تم الحل"), COUNTIFS('محمد السويركي'!$A$35:$A$70,$C$3,'محمد السويركي'!$B$35:$B$70,$F$3,'محمد السويركي'!$G$35:$G$70,"تم الحل")))) -> 2 | F7: =IF(AND($C$3="جميع الأسابيع",$F$3="جميع المجمعات"), 'محمد السويركي'!D7, IF($C$3="جميع الأسابيع", COUNTIFS('محمد السويركي'!$B$35:$B$70,$F$3,'محمد السويركي'!$G$35:$G$70,"مستمرة"), IF($F$3="جميع المجمعات", COUNTIFS('محمد السويركي'!$A$35:$A$70,$C$3,'محمد السويركي'!$G$35:$G$70,"مستمرة"), COUNTIFS('محمد السويركي'!$A$35:$A$70,$C$3,'محمد السويركي'!$B$35:$B$70,$F$3,'محمد السويركي'!$G$35:$G$70,"مستمرة")))) -> 0 | G7: =IFERROR(E7/(E7+F7), 0) -> 1 | H7: =IF(B7=0, "لا توجد بيانات", IF(F7=0, "مكتمل ومغلق", "قيد المتابعة")) -> مكتمل ومغلق
A8: خالد عبد ربه | B8: =IF(AND($C$3="جميع الأسابيع",$F$3="جميع المجمعات"), 'خالد عبد ربه'!D3, IF($C$3="جميع الأسابيع", COUNTIF('خالد عبد ربه'!$C$13:$C$32,$F$3)+COUNTIF('خالد عبد ربه'!$B$35:$B$70,$F$3), IF($F$3="جميع المجمعات", COUNTIF('خالد عبد ربه'!$A$13:$A$32,$C$3)+COUNTIF('خالد عبد ربه'!$A$35:$A$70,$C$3), COUNTIFS('خالد عبد ربه'!$A$13:$A$32,$C$3,'خالد عبد ربه'!$C$13:$C$32,$F$3)+COUNTIFS('خالد عبد ربه'!$A$35:$A$70,$C$3,'خالد عبد ربه'!$B$35:$B$70,$F$3)))) -> 0 | C8: =IF(AND($C$3="جميع الأسابيع",$F$3="جميع المجمعات"), 'خالد عبد ربه'!D4, IF($C$3="جميع الأسابيع", COUNTIF('خالد عبد ربه'!$C$13:$C$32,$F$3), IF($F$3="جميع المجمعات", COUNTIF('خالد عبد ربه'!$A$13:$A$32,$C$3), COUNTIFS('خالد عبد ربه'!$A$13:$A$32,$C$3,'خالد عبد ربه'!$C$13:$C$32,$F$3)))) -> 0 | D8: =IF(AND($C$3="جميع الأسابيع",$F$3="جميع المجمعات"), 'خالد عبد ربه'!D5, IF($C$3="جميع الأسابيع", COUNTIF('خالد عبد ربه'!$B$35:$B$70,$F$3), IF($F$3="جميع المجمعات", COUNTIF('خالد عبد ربه'!$A$35:$A$70,$C$3), COUNTIFS('خالد عبد ربه'!$A$35:$A$70,$C$3,'خالد عبد ربه'!$B$35:$B$70,$F$3)))) -> 0 | E8: =IF(AND($C$3="جميع الأسابيع",$F$3="جميع المجمعات"), 'خالد عبد ربه'!D6, IF($C$3="جميع الأسابيع", COUNTIFS('خالد عبد ربه'!$B$35:$B$70,$F$3,'خالد عبد ربه'!$G$35:$G$70,"تم الحل"), IF($F$3="جميع المجمعات", COUNTIFS('خالد عبد ربه'!$A$35:$A$70,$C$3,'خالد عبد ربه'!$G$35:$G$70,"تم الحل"), COUNTIFS('خالد عبد ربه'!$A$35:$A$70,$C$3,'خالد عبد ربه'!$B$35:$B$70,$F$3,'خالد عبد ربه'!$G$35:$G$70,"تم الحل")))) -> 0 | F8: =IF(AND($C$3="جميع الأسابيع",$F$3="جميع المجمعات"), 'خالد عبد ربه'!D7, IF($C$3="جميع الأسابيع", COUNTIFS('خالد عبد ربه'!$B$35:$B$70,$F$3,'خالد عبد ربه'!$G$35:$G$70,"مستمرة"), IF($F$3="جميع المجمعات", COUNTIFS('خالد عبد ربه'!$A$35:$A$70,$C$3,'خالد عبد ربه'!$G$35:$G$70,"مستمرة"), COUNTIFS('خالد عبد ربه'!$A$35:$A$70,$C$3,'خالد عبد ربه'!$B$35:$B$70,$F$3,'خالد عبد ربه'!$G$35:$G$70,"مستمرة")))) -> 0 | G8: =IFERROR(E8/(E8+F8), 0) -> 0 | H8: =IF(B8=0, "لا توجد بيانات", IF(F8=0, "مكتمل ومغلق", "قيد المتابعة")) -> لا توجد بيانات
A9: ناريمان الحجاجرة | B9: =IF(AND($C$3="جميع الأسابيع",$F$3="جميع المجمعات"), 'ناريمان الحجاجرة'!D3, IF($C$3="جميع الأسابيع", COUNTIF('ناريمان الحجاجرة'!$C$13:$C$32,$F$3)+COUNTIF('ناريمان الحجاجرة'!$B$35:$B$70,$F$3), IF($F$3="جميع المجمعات", COUNTIF('ناريمان الحجاجرة'!$A$13:$A$32,$C$3)+COUNTIF('ناريمان الحجاجرة'!$A$35:$A$70,$C$3), COUNTIFS('ناريمان الحجاجرة'!$A$13:$A$32,$C$3,'ناريمان الحجاجرة'!$C$13:$C$32,$F$3)+COUNTIFS('ناريمان الحجاجرة'!$A$35:$A$70,$C$3,'ناريمان الحجاجرة'!$B$35:$B$70,$F$3)))) -> 17 | C9: =IF(AND($C$3="جميع الأسابيع",$F$3="جميع المجمعات"), 'ناريمان الحجاجرة'!D4, IF($C$3="جميع الأسابيع", COUNTIF('ناريمان الحجاجرة'!$C$13:$C$32,$F$3), IF($F$3="جميع المجمعات", COUNTIF('ناريمان الحجاجرة'!$A$13:$A$32,$C$3), COUNTIFS('ناريمان الحجاجرة'!$A$13:$A$32,$C$3,'ناريمان الحجاجرة'!$C$13:$C$32,$F$3)))) -> 12 | D9: =IF(AND($C$3="جميع الأسابيع",$F$3="جميع المجمعات"), 'ناريمان الحجاجرة'!D5, IF($C$3="جميع الأسابيع", COUNTIF('ناريمان الحجاجرة'!$B$35:$B$70,$F$3), IF($F$3="جميع المجمعات", COUNTIF('ناريمان الحجاجرة'!$A$35:$A$70,$C$3), COUNTIFS('ناريمان الحجاجرة'!$A$35:$A$70,$C$3,'ناريمان الحجاجرة'!$B$35:$B$70,$F$3)))) -> 5 | E9: =IF(AND($C$3="جميع الأسابيع",$F$3="جميع المجمعات"), 'ناريمان الحجاجرة'!D6, IF($C$3="جميع الأسابيع", COUNTIFS('ناريمان الحجاجرة'!$B$35:$B$70,$F$3,'ناريمان الحجاجرة'!$G$35:$G$70,"تم الحل"), IF($F$3="جميع المجمعات", COUNTIFS('ناريمان الحجاجرة'!$A$35:$A$70,$C$3,'ناريمان الحجاجرة'!$G$35:$G$70,"تم الحل"), COUNTIFS('ناريمان الحجاجرة'!$A$35:$A$70,$C$3,'ناريمان الحجاجرة'!$B$35:$B$70,$F$3,'ناريمان الحجاجرة'!$G$35:$G$70,"تم الحل")))) -> 0 | F9: =IF(AND($C$3="جميع الأسابيع",$F$3="جميع المجمعات"), 'ناريمان الحجاجرة'!D7, IF($C$3="جميع الأسابيع", COUNTIFS('ناريمان الحجاجرة'!$B$35:$B$70,$F$3,'ناريمان الحجاجرة'!$G$35:$G$70,"مستمرة"), IF($F$3="جميع المجمعات", COUNTIFS('ناريمان الحجاجرة'!$A$35:$A$70,$C$3,'ناريمان الحجاجرة'!$G$35:$G$70,"مستمرة"), COUNTIFS('ناريمان الحجاجرة'!$A$35:$A$70,$C$3,'ناريمان الحجاجرة'!$B$35:$B$70,$F$3,'ناريمان الحجاجرة'!$G$35:$G$70,"مستمرة")))) -> 0 | G9: =IFERROR(E9/(E9+F9), 0) -> 0 | H9: =IF(B9=0, "لا توجد بيانات", IF(F9=0, "مكتمل ومغلق", "قيد المتابعة")) -> مكتمل ومغلق
A10: مروة حسان | B10: =IF(AND($C$3="جميع الأسابيع",$F$3="جميع المجمعات"), 'مروة حسان'!D3, IF($C$3="جميع الأسابيع", COUNTIF('مروة حسان'!$C$13:$C$32,$F$3)+COUNTIF('مروة حسان'!$B$35:$B$70,$F$3), IF($F$3="جميع المجمعات", COUNTIF('مروة حسان'!$A$13:$A$32,$C$3)+COUNTIF('مروة حسان'!$A$35:$A$70,$C$3), COUNTIFS('مروة حسان'!$A$13:$A$32,$C$3,'مروة حسان'!$C$13:$C$32,$F$3)+COUNTIFS('مروة حسان'!$A$35:$A$70,$C$3,'مروة حسان'!$B$35:$B$70,$F$3)))) -> 23 | C10: =IF(AND($C$3="جميع الأسابيع",$F$3="جميع المجمعات"), 'مروة حسان'!D4, IF($C$3="جميع الأسابيع", COUNTIF('مروة حسان'!$C$13:$C$32,$F$3), IF($F$3="جميع المجمعات", COUNTIF('مروة حسان'!$A$13:$A$32,$C$3), COUNTIFS('مروة حسان'!$A$13:$A$32,$C$3,'مروة حسان'!$C$13:$C$32,$F$3)))) -> 15 | D10: =IF(AND($C$3="جميع الأسابيع",$F$3="جميع المجمعات"), 'مروة حسان'!D5, IF($C$3="جميع الأسابيع", COUNTIF('مروة حسان'!$B$35:$B$70,$F$3), IF($F$3="جميع المجمعات", COUNTIF('مروة حسان'!$A$35:$A$70,$C$3), COUNTIFS('مروة حسان'!$A$35:$A$70,$C$3,'مروة حسان'!$B$35:$B$70,$F$3)))) -> 8 | E10: =IF(AND($C$3="جميع الأسابيع",$F$3="جميع المجمعات"), 'مروة حسان'!D6, IF($C$3="جميع الأسابيع", COUNTIFS('مروة حسان'!$B$35:$B$70,$F$3,'مروة حسان'!$G$35:$G$70,"تم الحل"), IF($F$3="جميع المجمعات", COUNTIFS('مروة حسان'!$A$35:$A$70,$C$3,'مروة حسان'!$G$35:$G$70,"تم الحل"), COUNTIFS('مروة حسان'!$A$35:$A$70,$C$3,'مروة حسان'!$B$35:$B$70,$F$3,'مروة حسان'!$G$35:$G$70,"تم الحل")))) -> 8 | F10: =IF(AND($C$3="جميع الأسابيع",$F$3="جميع المجمعات"), 'مروة حسان'!D7, IF($C$3="جميع الأسابيع", COUNTIFS('مروة حسان'!$B$35:$B$70,$F$3,'مروة حسان'!$G$35:$G$70,"مستمرة"), IF($F$3="جميع المجمعات", COUNTIFS('مروة حسان'!$A$35:$A$70,$C$3,'مروة حسان'!$G$35:$G$70,"مستمرة"), COUNTIFS('مروة حسان'!$A$35:$A$70,$C$3,'مروة حسان'!$B$35:$B$70,$F$3,'مروة حسان'!$G$35:$G$70,"مستمرة")))) -> 0 | G10: =IFERROR(E10/(E10+F10), 0) -> 1 | H10: =IF(B10=0, "لا توجد بيانات", IF(F10=0, "مكتمل ومغلق", "قيد المتابعة")) -> مكتمل ومغلق
A11: إيمان المبارك | B11: =IF(AND($C$3="جميع الأسابيع",$F$3="جميع المجمعات"), 'إيمان المبارك'!D3, IF($C$3="جميع الأسابيع", COUNTIF('إيمان المبارك'!$C$13:$C$32,$F$3)+COUNTIF('إيمان المبارك'!$B$35:$B$70,$F$3), IF($F$3="جميع المجمعات", COUNTIF('إيمان المبارك'!$A$13:$A$32,$C$3)+COUNTIF('إيمان المبارك'!$A$35:$A$70,$C$3), COUNTIFS('إيمان المبارك'!$A$13:$A$32,$C$3,'إيمان المبارك'!$C$13:$C$32,$F$3)+COUNTIFS('إيمان المبارك'!$A$35:$A$70,$C$3,'إيمان المبارك'!$B$35:$B$70,$F$3)))) -> 0 | C11: =IF(AND($C$3="جميع الأسابيع",$F$3="جميع المجمعات"), 'إيمان المبارك'!D4, IF($C$3="جميع الأسابيع", COUNTIF('إيمان المبارك'!$C$13:$C$32,$F$3), IF($F$3="جميع المجمعات", COUNTIF('إيمان المبارك'!$A$13:$A$32,$C$3), COUNTIFS('إيمان المبارك'!$A$13:$A$32,$C$3,'إيمان المبارك'!$C$13:$C$32,$F$3)))) -> 0 | D11: =IF(AND($C$3="جميع الأسابيع",$F$3="جميع المجمعات"), 'إيمان المبارك'!D5, IF($C$3="جميع الأسابيع", COUNTIF('إيمان المبارك'!$B$35:$B$70,$F$3), IF($F$3="جميع المجمعات", COUNTIF('إيمان المبارك'!$A$35:$A$70,$C$3), COUNTIFS('إيمان المبارك'!$A$35:$A$70,$C$3,'إيمان المبارك'!$B$35:$B$70,$F$3)))) -> 0 | E11: =IF(AND($C$3="جميع الأسابيع",$F$3="جميع المجمعات"), 'إيمان المبارك'!D6, IF($C$3="جميع الأسابيع", COUNTIFS('إيمان المبارك'!$B$35:$B$70,$F$3,'إيمان المبارك'!$G$35:$G$70,"تم الحل"), IF($F$3="جميع المجمعات", COUNTIFS('إيمان المبارك'!$A$35:$A$70,$C$3,'إيمان المبارك'!$G$35:$G$70,"تم الحل"), COUNTIFS('إيمان المبارك'!$A$35:$A$70,$C$3,'إيمان المبارك'!$B$35:$B$70,$F$3,'إيمان المبارك'!$G$35:$G$70,"تم الحل")))) -> 0 | F11: =IF(AND($C$3="جميع الأسابيع",$F$3="جميع المجمعات"), 'إيمان المبارك'!D7, IF($C$3="جميع الأسابيع", COUNTIFS('إيمان المبارك'!$B$35:$B$70,$F$3,'إيمان المبارك'!$G$35:$G$70,"مستمرة"), IF($F$3="جميع المجمعات", COUNTIFS('إيمان المبارك'!$A$35:$A$70,$C$3,'إيمان المبارك'!$G$35:$G$70,"مستمرة"), COUNTIFS('إيمان المبارك'!$A$35:$A$70,$C$3,'إيمان المبارك'!$B$35:$B$70,$F$3,'إيمان المبارك'!$G$35:$G$70,"مستمرة")))) -> 0 | G11: =IFERROR(E11/(E11+F11), 0) -> 0 | H11: =IF(B11=0, "لا توجد بيانات", IF(F11=0, "مكتمل ومغلق", "قيد المتابعة")) -> لا توجد بيانات
A12: الإجمالي العام للقسم | B12: =SUM(B6:B11) -> 78 | C12: =SUM(C6:C11) -> 55 | D12: =SUM(D6:D11) -> 23 | E12: =SUM(E6:E11) -> 15 | F12: =SUM(F6:F11) -> 3 | G12: =IFERROR(E12/(E12+F12), 0) -> 0.83333333 | H12: -
A14: ملخص المؤشرات والملاحظات حسب المجمع التعليمي (يتفاعل تلقائياً مع فلتر الأسبوع بأعلى الصفحة)
A15: المجمع التعليمي | B15: إجمالي المعلمين (تميز/تحسين) | C15: المعلمون المتميزون | D15: الملاحظات وفرص التطوير | E15: الملاحظات المحلولة | F15: الملاحظات المستمرة | G15: نسبة الإغلاق | H15: حالة المجمع
A16: رواد الإزدهار | B16: =C16+D16 -> 11 | C16: =IF($C$3="جميع الأسابيع", COUNTIF('السيد سالم'!$C$13:$C$32, $A16)+COUNTIF('محمد السويركي'!$C$13:$C$32, $A16)+COUNTIF('خالد عبد ربه'!$C$13:$C$32, $A16)+COUNTIF('ناريمان الحجاجرة'!$C$13:$C$32, $A16)+COUNTIF('مروة حسان'!$C$13:$C$32, $A16)+COUNTIF('إيمان المبارك'!$C$13:$C$32, $A16), COUNTIFS('السيد سالم'!$C$13:$C$32, $A16, 'السيد سالم'!$A$13:$A$32, $C$3)+COUNTIFS('محمد السويركي'!$C$13:$C$32, $A16, 'محمد السويركي'!$A$13:$A$32, $C$3)+COUNTIFS('خالد عبد ربه'!$C$13:$C$32, $A16, 'خالد عبد ربه'!$A$13:$A$32, $C$3)+COUNTIFS('ناريمان الحجاجرة'!$C$13:$C$32, $A16, 'ناريمان الحجاجرة'!$A$13:$A$32, $C$3)+COUNTIFS('مروة حسان'!$C$13:$C$32, $A16, 'مروة حسان'!$A$13:$A$32, $C$3)+COUNTIFS('إيمان المبارك'!$C$13:$C$32, $A16, 'إيمان المبارك'!$A$13:$A$32, $C$3)) -> 6 | D16: =IF($C$3="جميع الأسابيع", COUNTIF('السيد سالم'!$B$35:$B$70, $A16)+COUNTIF('محمد السويركي'!$B$35:$B$70, $A16)+COUNTIF('خالد عبد ربه'!$B$35:$B$70, $A16)+COUNTIF('ناريمان الحجاجرة'!$B$35:$B$70, $A16)+COUNTIF('مروة حسان'!$B$35:$B$70, $A16)+COUNTIF('إيمان المبارك'!$B$35:$B$70, $A16), COUNTIFS('السيد سالم'!$B$35:$B$70, $A16, 'السيد سالم'!$A$35:$A$70, $C$3)+COUNTIFS('محمد السويركي'!$B$35:$B$70, $A16, 'محمد السويركي'!$A$35:$A$70, $C$3)+COUNTIFS('خالد عبد ربه'!$B$35:$B$70, $A16, 'خالد عبد ربه'!$A$35:$A$70, $C$3)+COUNTIFS('ناريمان الحجاجرة'!$B$35:$B$70, $A16, 'ناريمان الحجاجرة'!$A$35:$A$70, $C$3)+COUNTIFS('مروة حسان'!$B$35:$B$70, $A16, 'مروة حسان'!$A$35:$A$70, $C$3)+COUNTIFS('إيمان المبارك'!$B$35:$B$70, $A16, 'إيمان المبارك'!$A$35:$A$70, $C$3)) -> 5 | E16: =IF($C$3="جميع الأسابيع", COUNTIFS('السيد سالم'!$B$35:$B$70, $A16, 'السيد سالم'!$G$35:$G$70, "تم الحل")+COUNTIFS('محمد السويركي'!$B$35:$B$70, $A16, 'محمد السويركي'!$G$35:$G$70, "تم الحل")+COUNTIFS('خالد عبد ربه'!$B$35:$B$70, $A16, 'خالد عبد ربه'!$G$35:$G$70, "تم الحل")+COUNTIFS('ناريمان الحجاجرة'!$B$35:$B$70, $A16, 'ناريمان الحجاجرة'!$G$35:$G$70, "تم الحل")+COUNTIFS('مروة حسان'!$B$35:$B$70, $A16, 'مروة حسان'!$G$35:$G$70, "تم الحل")+COUNTIFS('إيمان المبارك'!$B$35:$B$70, $A16, 'إيمان المبارك'!$G$35:$G$70, "تم الحل"), COUNTIFS('السيد سالم'!$B$35:$B$70, $A16, 'السيد سالم'!$A$35:$A$70, $C$3, 'السيد سالم'!$G$35:$G$70, "تم الحل")+COUNTIFS('محمد السويركي'!$B$35:$B$70, $A16, 'محمد السويركي'!$A$35:$A$70, $C$3, 'محمد السويركي'!$G$35:$G$70, "تم الحل")+COUNTIFS('خالد عبد ربه'!$B$35:$B$70, $A16, 'خالد عبد ربه'!$A$35:$A$70, $C$3, 'خالد عبد ربه'!$G$35:$G$70, "تم الحل")+COUNTIFS('ناريمان الحجاجرة'!$B$35:$B$70, $A16, 'ناريمان الحجاجرة'!$A$35:$A$70, $C$3, 'ناريمان الحجاجرة'!$G$35:$G$70, "تم الحل")+COUNTIFS('مروة حسان'!$B$35:$B$70, $A16, 'مروة حسان'!$A$35:$A$70, $C$3, 'مروة حسان'!$G$35:$G$70, "تم الحل")+COUNTIFS('إيمان المبارك'!$B$35:$B$70, $A16, 'إيمان المبارك'!$A$35:$A$70, $C$3, 'إيمان المبارك'!$G$35:$G$70, "تم الحل")) -> 4 | F16: =IF($C$3="جميع الأسابيع", COUNTIFS('السيد سالم'!$B$35:$B$70, $A16, 'السيد سالم'!$G$35:$G$70, "مستمرة")+COUNTIFS('محمد السويركي'!$B$35:$B$70, $A16, 'محمد السويركي'!$G$35:$G$70, "مستمرة")+COUNTIFS('خالد عبد ربه'!$B$35:$B$70, $A16, 'خالد عبد ربه'!$G$35:$G$70, "مستمرة")+COUNTIFS('ناريمان الحجاجرة'!$B$35:$B$70, $A16, 'ناريمان الحجاجرة'!$G$35:$G$70, "مستمرة")+COUNTIFS('مروة حسان'!$B$35:$B$70, $A16, 'مروة حسان'!$G$35:$G$70, "مستمرة")+COUNTIFS('إيمان المبارك'!$B$35:$B$70, $A16, 'إيمان المبارك'!$G$35:$G$70, "مستمرة"), COUNTIFS('السيد سالم'!$B$35:$B$70, $A16, 'السيد سالم'!$A$35:$A$70, $C$3, 'السيد سالم'!$G$35:$G$70, "مستمرة")+COUNTIFS('محمد السويركي'!$B$35:$B$70, $A16, 'محمد السويركي'!$A$35:$A$70, $C$3, 'محمد السويركي'!$G$35:$G$70, "مستمرة")+COUNTIFS('خالد عبد ربه'!$B$35:$B$70, $A16, 'خالد عبد ربه'!$A$35:$A$70, $C$3, 'خالد عبد ربه'!$G$35:$G$70, "مستمرة")+COUNTIFS('ناريمان الحجاجرة'!$B$35:$B$70, $A16, 'ناريمان الحجاجرة'!$A$35:$A$70, $C$3, 'ناريمان الحجاجرة'!$G$35:$G$70, "مستمرة")+COUNTIFS('مروة حسان'!$B$35:$B$70, $A16, 'مروة حسان'!$A$35:$A$70, $C$3, 'مروة حسان'!$G$35:$G$70, "مستمرة")+COUNTIFS('إيمان المبارك'!$B$35:$B$70, $A16, 'إيمان المبارك'!$A$35:$A$70, $C$3, 'إيمان المبارك'!$G$35:$G$70, "مستمرة")) -> 1 | G16: =IFERROR(E16/(E16+F16), 0) -> 0.8 | H16: =IF(D16=0, "لا توجد ملاحظات", IF(F16=0, "تم إغلاق الملاحظات", "يوجد ملاحظات مستمرة")) -> يوجد ملاحظات مستمرة
A17: رواد الغدير | B17: =C17+D17 -> 2 | C17: =IF($C$3="جميع الأسابيع", COUNTIF('السيد سالم'!$C$13:$C$32, $A17)+COUNTIF('محمد السويركي'!$C$13:$C$32, $A17)+COUNTIF('خالد عبد ربه'!$C$13:$C$32, $A17)+COUNTIF('ناريمان الحجاجرة'!$C$13:$C$32, $A17)+COUNTIF('مروة حسان'!$C$13:$C$32, $A17)+COUNTIF('إيمان المبارك'!$C$13:$C$32, $A17), COUNTIFS('السيد سالم'!$C$13:$C$32, $A17, 'السيد سالم'!$A$13:$A$32, $C$3)+COUNTIFS('محمد السويركي'!$C$13:$C$32, $A17, 'محمد السويركي'!$A$13:$A$32, $C$3)+COUNTIFS('خالد عبد ربه'!$C$13:$C$32, $A17, 'خالد عبد ربه'!$A$13:$A$32, $C$3)+COUNTIFS('ناريمان الحجاجرة'!$C$13:$C$32, $A17, 'ناريمان الحجاجرة'!$A$13:$A$32, $C$3)+COUNTIFS('مروة حسان'!$C$13:$C$32, $A17, 'مروة حسان'!$A$13:$A$32, $C$3)+COUNTIFS('إيمان المبارك'!$C$13:$C$32, $A17, 'إيمان المبارك'!$A$13:$A$32, $C$3)) -> 2 | D17: =IF($C$3="جميع الأسابيع", COUNTIF('السيد سالم'!$B$35:$B$70, $A17)+COUNTIF('محمد السويركي'!$B$35:$B$70, $A17)+COUNTIF('خالد عبد ربه'!$B$35:$B$70, $A17)+COUNTIF('ناريمان الحجاجرة'!$B$35:$B$70, $A17)+COUNTIF('مروة حسان'!$B$35:$B$70, $A17)+COUNTIF('إيمان المبارك'!$B$35:$B$70, $A17), COUNTIFS('السيد سالم'!$B$35:$B$70, $A17, 'السيد سالم'!$A$35:$A$70, $C$3)+COUNTIFS('محمد السويركي'!$B$35:$B$70, $A17, 'محمد السويركي'!$A$35:$A$70, $C$3)+COUNTIFS('خالد عبد ربه'!$B$35:$B$70, $A17, 'خالد عبد ربه'!$A$35:$A$70, $C$3)+COUNTIFS('ناريمان الحجاجرة'!$B$35:$B$70, $A17, 'ناريمان الحجاجرة'!$A$35:$A$70, $C$3)+COUNTIFS('مروة حسان'!$B$35:$B$70, $A17, 'مروة حسان'!$A$35:$A$70, $C$3)+COUNTIFS('إيمان المبارك'!$B$35:$B$70, $A17, 'إيمان المبارك'!$A$35:$A$70, $C$3)) -> 0 | E17: =IF($C$3="جميع الأسابيع", COUNTIFS('السيد سالم'!$B$35:$B$70, $A17, 'السيد سالم'!$G$35:$G$70, "تم الحل")+COUNTIFS('محمد السويركي'!$B$35:$B$70, $A17, 'محمد السويركي'!$G$35:$G$70, "تم الحل")+COUNTIFS('خالد عبد ربه'!$B$35:$B$70, $A17, 'خالد عبد ربه'!$G$35:$G$70, "تم الحل")+COUNTIFS('ناريمان الحجاجرة'!$B$35:$B$70, $A17, 'ناريمان الحجاجرة'!$G$35:$G$70, "تم الحل")+COUNTIFS('مروة حسان'!$B$35:$B$70, $A17, 'مروة حسان'!$G$35:$G$70, "تم الحل")+COUNTIFS('إيمان المبارك'!$B$35:$B$70, $A17, 'إيمان المبارك'!$G$35:$G$70, "تم الحل"), COUNTIFS('السيد سالم'!$B$35:$B$70, $A17, 'السيد سالم'!$A$35:$A$70, $C$3, 'السيد سالم'!$G$35:$G$70, "تم الحل")+COUNTIFS('محمد السويركي'!$B$35:$B$70, $A17, 'محمد السويركي'!$A$35:$A$70, $C$3, 'محمد السويركي'!$G$35:$G$70, "تم الحل")+COUNTIFS('خالد عبد ربه'!$B$35:$B$70, $A17, 'خالد عبد ربه'!$A$35:$A$70, $C$3, 'خالد عبد ربه'!$G$35:$G$70, "تم الحل")+COUNTIFS('ناريمان الحجاجرة'!$B$35:$B$70, $A17, 'ناريمان الحجاجرة'!$A$35:$A$70, $C$3, 'ناريمان الحجاجرة'!$G$35:$G$70, "تم الحل")+COUNTIFS('مروة حسان'!$B$35:$B$70, $A17, 'مروة حسان'!$A$35:$A$70, $C$3, 'مروة حسان'!$G$35:$G$70, "تم الحل")+COUNTIFS('إيمان المبارك'!$B$35:$B$70, $A17, 'إيمان المبارك'!$A$35:$A$70, $C$3, 'إيمان المبارك'!$G$35:$G$70, "تم الحل")) -> 0 | F17: =IF($C$3="جميع الأسابيع", COUNTIFS('السيد سالم'!$B$35:$B$70, $A17, 'السيد سالم'!$G$35:$G$70, "مستمرة")+COUNTIFS('محمد السويركي'!$B$35:$B$70, $A17, 'محمد السويركي'!$G$35:$G$70, "مستمرة")+COUNTIFS('خالد عبد ربه'!$B$35:$B$70, $A17, 'خالد عبد ربه'!$G$35:$G$70, "مستمرة")+COUNTIFS('ناريمان الحجاجرة'!$B$35:$B$70, $A17, 'ناريمان الحجاجرة'!$G$35:$G$70, "مستمرة")+COUNTIFS('مروة حسان'!$B$35:$B$70, $A17, 'مروة حسان'!$G$35:$G$70, "مستمرة")+COUNTIFS('إيمان المبارك'!$B$35:$B$70, $A17, 'إيمان المبارك'!$G$35:$G$70, "مستمرة"), COUNTIFS('السيد سالم'!$B$35:$B$70, $A17, 'السيد سالم'!$A$35:$A$70, $C$3, 'السيد سالم'!$G$35:$G$70, "مستمرة")+COUNTIFS('محمد السويركي'!$B$35:$B$70, $A17, 'محمد السويركي'!$A$35:$A$70, $C$3, 'محمد السويركي'!$G$35:$G$70, "مستمرة")+COUNTIFS('خالد عبد ربه'!$B$35:$B$70, $A17, 'خالد عبد ربه'!$A$35:$A$70, $C$3, 'خالد عبد ربه'!$G$35:$G$70, "مستمرة")+COUNTIFS('ناريمان الحجاجرة'!$B$35:$B$70, $A17, 'ناريمان الحجاجرة'!$A$35:$A$70, $C$3, 'ناريمان الحجاجرة'!$G$35:$G$70, "مستمرة")+COUNTIFS('مروة حسان'!$B$35:$B$70, $A17, 'مروة حسان'!$A$35:$A$70, $C$3, 'مروة حسان'!$G$35:$G$70, "مستمرة")+COUNTIFS('إيمان المبارك'!$B$35:$B$70, $A17, 'إيمان المبارك'!$A$35:$A$70, $C$3, 'إيمان المبارك'!$G$35:$G$70, "مستمرة")) -> 0 | G17: =IFERROR(E17/(E17+F17), 0) -> 0 | H17: =IF(D17=0, "لا توجد ملاحظات", IF(F17=0, "تم إغلاق الملاحظات", "يوجد ملاحظات مستمرة")) -> لا توجد ملاحظات
A18: رواد عرقة | B18: =C18+D18 -> 6 | C18: =IF($C$3="جميع الأسابيع", COUNTIF('السيد سالم'!$C$13:$C$32, $A18)+COUNTIF('محمد السويركي'!$C$13:$C$32, $A18)+COUNTIF('خالد عبد ربه'!$C$13:$C$32, $A18)+COUNTIF('ناريمان الحجاجرة'!$C$13:$C$32, $A18)+COUNTIF('مروة حسان'!$C$13:$C$32, $A18)+COUNTIF('إيمان المبارك'!$C$13:$C$32, $A18), COUNTIFS('السيد سالم'!$C$13:$C$32, $A18, 'السيد سالم'!$A$13:$A$32, $C$3)+COUNTIFS('محمد السويركي'!$C$13:$C$32, $A18, 'محمد السويركي'!$A$13:$A$32, $C$3)+COUNTIFS('خالد عبد ربه'!$C$13:$C$32, $A18, 'خالد عبد ربه'!$A$13:$A$32, $C$3)+COUNTIFS('ناريمان الحجاجرة'!$C$13:$C$32, $A18, 'ناريمان الحجاجرة'!$A$13:$A$32, $C$3)+COUNTIFS('مروة حسان'!$C$13:$C$32, $A18, 'مروة حسان'!$A$13:$A$32, $C$3)+COUNTIFS('إيمان المبارك'!$C$13:$C$32, $A18, 'إيمان المبارك'!$A$13:$A$32, $C$3)) -> 3 | D18: =IF($C$3="جميع الأسابيع", COUNTIF('السيد سالم'!$B$35:$B$70, $A18)+COUNTIF('محمد السويركي'!$B$35:$B$70, $A18)+COUNTIF('خالد عبد ربه'!$B$35:$B$70, $A18)+COUNTIF('ناريمان الحجاجرة'!$B$35:$B$70, $A18)+COUNTIF('مروة حسان'!$B$35:$B$70, $A18)+COUNTIF('إيمان المبارك'!$B$35:$B$70, $A18), COUNTIFS('السيد سالم'!$B$35:$B$70, $A18, 'السيد سالم'!$A$35:$A$70, $C$3)+COUNTIFS('محمد السويركي'!$B$35:$B$70, $A18, 'محمد السويركي'!$A$35:$A$70, $C$3)+COUNTIFS('خالد عبد ربه'!$B$35:$B$70, $A18, 'خالد عبد ربه'!$A$35:$A$70, $C$3)+COUNTIFS('ناريمان الحجاجرة'!$B$35:$B$70, $A18, 'ناريمان الحجاجرة'!$A$35:$A$70, $C$3)+COUNTIFS('مروة حسان'!$B$35:$B$70, $A18, 'مروة حسان'!$A$35:$A$70, $C$3)+COUNTIFS('إيمان المبارك'!$B$35:$B$70, $A18, 'إيمان المبارك'!$A$35:$A$70, $C$3)) -> 3 | E18: =IF($C$3="جميع الأسابيع", COUNTIFS('السيد سالم'!$B$35:$B$70, $A18, 'السيد سالم'!$G$35:$G$70, "تم الحل")+COUNTIFS('محمد السويركي'!$B$35:$B$70, $A18, 'محمد السويركي'!$G$35:$G$70, "تم الحل")+COUNTIFS('خالد عبد ربه'!$B$35:$B$70, $A18, 'خالد عبد ربه'!$G$35:$G$70, "تم الحل")+COUNTIFS('ناريمان الحجاجرة'!$B$35:$B$70, $A18, 'ناريمان الحجاجرة'!$G$35:$G$70, "تم الحل")+COUNTIFS('مروة حسان'!$B$35:$B$70, $A18, 'مروة حسان'!$G$35:$G$70, "تم الحل")+COUNTIFS('إيمان المبارك'!$B$35:$B$70, $A18, 'إيمان المبارك'!$G$35:$G$70, "تم الحل"), COUNTIFS('السيد سالم'!$B$35:$B$70, $A18, 'السيد سالم'!$A$35:$A$70, $C$3, 'السيد سالم'!$G$35:$G$70, "تم الحل")+COUNTIFS('محمد السويركي'!$B$35:$B$70, $A18, 'محمد السويركي'!$A$35:$A$70, $C$3, 'محمد السويركي'!$G$35:$G$70, "تم الحل")+COUNTIFS('خالد عبد ربه'!$B$35:$B$70, $A18, 'خالد عبد ربه'!$A$35:$A$70, $C$3, 'خالد عبد ربه'!$G$35:$G$70, "تم الحل")+COUNTIFS('ناريمان الحجاجرة'!$B$35:$B$70, $A18, 'ناريمان الحجاجرة'!$A$35:$A$70, $C$3, 'ناريمان الحجاجرة'!$G$35:$G$70, "تم الحل")+COUNTIFS('مروة حسان'!$B$35:$B$70, $A18, 'مروة حسان'!$A$35:$A$70, $C$3, 'مروة حسان'!$G$35:$G$70, "تم الحل")+COUNTIFS('إيمان المبارك'!$B$35:$B$70, $A18, 'إيمان المبارك'!$A$35:$A$70, $C$3, 'إيمان المبارك'!$G$35:$G$70, "تم الحل")) -> 1 | F18: =IF($C$3="جميع الأسابيع", COUNTIFS('السيد سالم'!$B$35:$B$70, $A18, 'السيد سالم'!$G$35:$G$70, "مستمرة")+COUNTIFS('محمد السويركي'!$B$35:$B$70, $A18, 'محمد السويركي'!$G$35:$G$70, "مستمرة")+COUNTIFS('خالد عبد ربه'!$B$35:$B$70, $A18, 'خالد عبد ربه'!$G$35:$G$70, "مستمرة")+COUNTIFS('ناريمان الحجاجرة'!$B$35:$B$70, $A18, 'ناريمان الحجاجرة'!$G$35:$G$70, "مستمرة")+COUNTIFS('مروة حسان'!$B$35:$B$70, $A18, 'مروة حسان'!$G$35:$G$70, "مستمرة")+COUNTIFS('إيمان المبارك'!$B$35:$B$70, $A18, 'إيمان المبارك'!$G$35:$G$70, "مستمرة"), COUNTIFS('السيد سالم'!$B$35:$B$70, $A18, 'السيد سالم'!$A$35:$A$70, $C$3, 'السيد سالم'!$G$35:$G$70, "مستمرة")+COUNTIFS('محمد السويركي'!$B$35:$B$70, $A18, 'محمد السويركي'!$A$35:$A$70, $C$3, 'محمد السويركي'!$G$35:$G$70, "مستمرة")+COUNTIFS('خالد عبد ربه'!$B$35:$B$70, $A18, 'خالد عبد ربه'!$A$35:$A$70, $C$3, 'خالد عبد ربه'!$G$35:$G$70, "مستمرة")+COUNTIFS('ناريمان الحجاجرة'!$B$35:$B$70, $A18, 'ناريمان الحجاجرة'!$A$35:$A$70, $C$3, 'ناريمان الحجاجرة'!$G$35:$G$70, "مستمرة")+COUNTIFS('مروة حسان'!$B$35:$B$70, $A18, 'مروة حسان'!$A$35:$A$70, $C$3, 'مروة حسان'!$G$35:$G$70, "مستمرة")+COUNTIFS('إيمان المبارك'!$B$35:$B$70, $A18, 'إيمان المبارك'!$A$35:$A$70, $C$3, 'إيمان المبارك'!$G$35:$G$70, "مستمرة")) -> 2 | G18: =IFERROR(E18/(E18+F18), 0) -> 0.33333333 | H18: =IF(D18=0, "لا توجد ملاحظات", IF(F18=0, "تم إغلاق الملاحظات", "يوجد ملاحظات مستمرة")) -> يوجد ملاحظات مستمرة
A19: رواد أشبيلية | B19: =C19+D19 -> 17 | C19: =IF($C$3="جميع الأسابيع", COUNTIF('السيد سالم'!$C$13:$C$32, $A19)+COUNTIF('محمد السويركي'!$C$13:$C$32, $A19)+COUNTIF('خالد عبد ربه'!$C$13:$C$32, $A19)+COUNTIF('ناريمان الحجاجرة'!$C$13:$C$32, $A19)+COUNTIF('مروة حسان'!$C$13:$C$32, $A19)+COUNTIF('إيمان المبارك'!$C$13:$C$32, $A19), COUNTIFS('السيد سالم'!$C$13:$C$32, $A19, 'السيد سالم'!$A$13:$A$32, $C$3)+COUNTIFS('محمد السويركي'!$C$13:$C$32, $A19, 'محمد السويركي'!$A$13:$A$32, $C$3)+COUNTIFS('خالد عبد ربه'!$C$13:$C$32, $A19, 'خالد عبد ربه'!$A$13:$A$32, $C$3)+COUNTIFS('ناريمان الحجاجرة'!$C$13:$C$32, $A19, 'ناريمان الحجاجرة'!$A$13:$A$32, $C$3)+COUNTIFS('مروة حسان'!$C$13:$C$32, $A19, 'مروة حسان'!$A$13:$A$32, $C$3)+COUNTIFS('إيمان المبارك'!$C$13:$C$32, $A19, 'إيمان المبارك'!$A$13:$A$32, $C$3)) -> 12 | D19: =IF($C$3="جميع الأسابيع", COUNTIF('السيد سالم'!$B$35:$B$70, $A19)+COUNTIF('محمد السويركي'!$B$35:$B$70, $A19)+COUNTIF('خالد عبد ربه'!$B$35:$B$70, $A19)+COUNTIF('ناريمان الحجاجرة'!$B$35:$B$70, $A19)+COUNTIF('مروة حسان'!$B$35:$B$70, $A19)+COUNTIF('إيمان المبارك'!$B$35:$B$70, $A19), COUNTIFS('السيد سالم'!$B$35:$B$70, $A19, 'السيد سالم'!$A$35:$A$70, $C$3)+COUNTIFS('محمد السويركي'!$B$35:$B$70, $A19, 'محمد السويركي'!$A$35:$A$70, $C$3)+COUNTIFS('خالد عبد ربه'!$B$35:$B$70, $A19, 'خالد عبد ربه'!$A$35:$A$70, $C$3)+COUNTIFS('ناريمان الحجاجرة'!$B$35:$B$70, $A19, 'ناريمان الحجاجرة'!$A$35:$A$70, $C$3)+COUNTIFS('مروة حسان'!$B$35:$B$70, $A19, 'مروة حسان'!$A$35:$A$70, $C$3)+COUNTIFS('إيمان المبارك'!$B$35:$B$70, $A19, 'إيمان المبارك'!$A$35:$A$70, $C$3)) -> 5 | E19: =IF($C$3="جميع الأسابيع", COUNTIFS('السيد سالم'!$B$35:$B$70, $A19, 'السيد سالم'!$G$35:$G$70, "تم الحل")+COUNTIFS('محمد السويركي'!$B$35:$B$70, $A19, 'محمد السويركي'!$G$35:$G$70, "تم الحل")+COUNTIFS('خالد عبد ربه'!$B$35:$B$70, $A19, 'خالد عبد ربه'!$G$35:$G$70, "تم الحل")+COUNTIFS('ناريمان الحجاجرة'!$B$35:$B$70, $A19, 'ناريمان الحجاجرة'!$G$35:$G$70, "تم الحل")+COUNTIFS('مروة حسان'!$B$35:$B$70, $A19, 'مروة حسان'!$G$35:$G$70, "تم الحل")+COUNTIFS('إيمان المبارك'!$B$35:$B$70, $A19, 'إيمان المبارك'!$G$35:$G$70, "تم الحل"), COUNTIFS('السيد سالم'!$B$35:$B$70, $A19, 'السيد سالم'!$A$35:$A$70, $C$3, 'السيد سالم'!$G$35:$G$70, "تم الحل")+COUNTIFS('محمد السويركي'!$B$35:$B$70, $A19, 'محمد السويركي'!$A$35:$A$70, $C$3, 'محمد السويركي'!$G$35:$G$70, "تم الحل")+COUNTIFS('خالد عبد ربه'!$B$35:$B$70, $A19, 'خالد عبد ربه'!$A$35:$A$70, $C$3, 'خالد عبد ربه'!$G$35:$G$70, "تم الحل")+COUNTIFS('ناريمان الحجاجرة'!$B$35:$B$70, $A19, 'ناريمان الحجاجرة'!$A$35:$A$70, $C$3, 'ناريمان الحجاجرة'!$G$35:$G$70, "تم الحل")+COUNTIFS('مروة حسان'!$B$35:$B$70, $A19, 'مروة حسان'!$A$35:$A$70, $C$3, 'مروة حسان'!$G$35:$G$70, "تم الحل")+COUNTIFS('إيمان المبارك'!$B$35:$B$70, $A19, 'إيمان المبارك'!$A$35:$A$70, $C$3, 'إيمان المبارك'!$G$35:$G$70, "تم الحل")) -> 2 | F19: =IF($C$3="جميع الأسابيع", COUNTIFS('السيد سالم'!$B$35:$B$70, $A19, 'السيد سالم'!$G$35:$G$70, "مستمرة")+COUNTIFS('محمد السويركي'!$B$35:$B$70, $A19, 'محمد السويركي'!$G$35:$G$70, "مستمرة")+COUNTIFS('خالد عبد ربه'!$B$35:$B$70, $A19, 'خالد عبد ربه'!$G$35:$G$70, "مستمرة")+COUNTIFS('ناريمان الحجاجرة'!$B$35:$B$70, $A19, 'ناريمان الحجاجرة'!$G$35:$G$70, "مستمرة")+COUNTIFS('مروة حسان'!$B$35:$B$70, $A19, 'مروة حسان'!$G$35:$G$70, "مستمرة")+COUNTIFS('إيمان المبارك'!$B$35:$B$70, $A19, 'إيمان المبارك'!$G$35:$G$70, "مستمرة"), COUNTIFS('السيد سالم'!$B$35:$B$70, $A19, 'السيد سالم'!$A$35:$A$70, $C$3, 'السيد سالم'!$G$35:$G$70, "مستمرة")+COUNTIFS('محمد السويركي'!$B$35:$B$70, $A19, 'محمد السويركي'!$A$35:$A$70, $C$3, 'محمد السويركي'!$G$35:$G$70, "مستمرة")+COUNTIFS('خالد عبد ربه'!$B$35:$B$70, $A19, 'خالد عبد ربه'!$A$35:$A$70, $C$3, 'خالد عبد ربه'!$G$35:$G$70, "مستمرة")+COUNTIFS('ناريمان الحجاجرة'!$B$35:$B$70, $A19, 'ناريمان الحجاجرة'!$A$35:$A$70, $C$3, 'ناريمان الحجاجرة'!$G$35:$G$70, "مستمرة")+COUNTIFS('مروة حسان'!$B$35:$B$70, $A19, 'مروة حسان'!$A$35:$A$70, $C$3, 'مروة حسان'!$G$35:$G$70, "مستمرة")+COUNTIFS('إيمان المبارك'!$B$35:$B$70, $A19, 'إيمان المبارك'!$A$35:$A$70, $C$3, 'إيمان المبارك'!$G$35:$G$70, "مستمرة")) -> 0 | G19: =IFERROR(E19/(E19+F19), 0) -> 1 | H19: =IF(D19=0, "لا توجد ملاحظات", IF(F19=0, "تم إغلاق الملاحظات", "يوجد ملاحظات مستمرة")) -> تم إغلاق الملاحظات
A20: رواد الأندلس | B20: =C20+D20 -> 8 | C20: =IF($C$3="جميع الأسابيع", COUNTIF('السيد سالم'!$C$13:$C$32, $A20)+COUNTIF('محمد السويركي'!$C$13:$C$32, $A20)+COUNTIF('خالد عبد ربه'!$C$13:$C$32, $A20)+COUNTIF('ناريمان الحجاجرة'!$C$13:$C$32, $A20)+COUNTIF('مروة حسان'!$C$13:$C$32, $A20)+COUNTIF('إيمان المبارك'!$C$13:$C$32, $A20), COUNTIFS('السيد سالم'!$C$13:$C$32, $A20, 'السيد سالم'!$A$13:$A$32, $C$3)+COUNTIFS('محمد السويركي'!$C$13:$C$32, $A20, 'محمد السويركي'!$A$13:$A$32, $C$3)+COUNTIFS('خالد عبد ربه'!$C$13:$C$32, $A20, 'خالد عبد ربه'!$A$13:$A$32, $C$3)+COUNTIFS('ناريمان الحجاجرة'!$C$13:$C$32, $A20, 'ناريمان الحجاجرة'!$A$13:$A$32, $C$3)+COUNTIFS('مروة حسان'!$C$13:$C$32, $A20, 'مروة حسان'!$A$13:$A$32, $C$3)+COUNTIFS('إيمان المبارك'!$C$13:$C$32, $A20, 'إيمان المبارك'!$A$13:$A$32, $C$3)) -> 7 | D20: =IF($C$3="جميع الأسابيع", COUNTIF('السيد سالم'!$B$35:$B$70, $A20)+COUNTIF('محمد السويركي'!$B$35:$B$70, $A20)+COUNTIF('خالد عبد ربه'!$B$35:$B$70, $A20)+COUNTIF('ناريمان الحجاجرة'!$B$35:$B$70, $A20)+COUNTIF('مروة حسان'!$B$35:$B$70, $A20)+COUNTIF('إيمان المبارك'!$B$35:$B$70, $A20), COUNTIFS('السيد سالم'!$B$35:$B$70, $A20, 'السيد سالم'!$A$35:$A$70, $C$3)+COUNTIFS('محمد السويركي'!$B$35:$B$70, $A20, 'محمد السويركي'!$A$35:$A$70, $C$3)+COUNTIFS('خالد عبد ربه'!$B$35:$B$70, $A20, 'خالد عبد ربه'!$A$35:$A$70, $C$3)+COUNTIFS('ناريمان الحجاجرة'!$B$35:$B$70, $A20, 'ناريمان الحجاجرة'!$A$35:$A$70, $C$3)+COUNTIFS('مروة حسان'!$B$35:$B$70, $A20, 'مروة حسان'!$A$35:$A$70, $C$3)+COUNTIFS('إيمان المبارك'!$B$35:$B$70, $A20, 'إيمان المبارك'!$A$35:$A$70, $C$3)) -> 1 | E20: =IF($C$3="جميع الأسابيع", COUNTIFS('السيد سالم'!$B$35:$B$70, $A20, 'السيد سالم'!$G$35:$G$70, "تم الحل")+COUNTIFS('محمد السويركي'!$B$35:$B$70, $A20, 'محمد السويركي'!$G$35:$G$70, "تم الحل")+COUNTIFS('خالد عبد ربه'!$B$35:$B$70, $A20, 'خالد عبد ربه'!$G$35:$G$70, "تم الحل")+COUNTIFS('ناريمان الحجاجرة'!$B$35:$B$70, $A20, 'ناريمان الحجاجرة'!$G$35:$G$70, "تم الحل")+COUNTIFS('مروة حسان'!$B$35:$B$70, $A20, 'مروة حسان'!$G$35:$G$70, "تم الحل")+COUNTIFS('إيمان المبارك'!$B$35:$B$70, $A20, 'إيمان المبارك'!$G$35:$G$70, "تم الحل"), COUNTIFS('السيد سالم'!$B$35:$B$70, $A20, 'السيد سالم'!$A$35:$A$70, $C$3, 'السيد سالم'!$G$35:$G$70, "تم الحل")+COUNTIFS('محمد السويركي'!$B$35:$B$70, $A20, 'محمد السويركي'!$A$35:$A$70, $C$3, 'محمد السويركي'!$G$35:$G$70, "تم الحل")+COUNTIFS('خالد عبد ربه'!$B$35:$B$70, $A20, 'خالد عبد ربه'!$A$35:$A$70, $C$3, 'خالد عبد ربه'!$G$35:$G$70, "تم الحل")+COUNTIFS('ناريمان الحجاجرة'!$B$35:$B$70, $A20, 'ناريمان الحجاجرة'!$A$35:$A$70, $C$3, 'ناريمان الحجاجرة'!$G$35:$G$70, "تم الحل")+COUNTIFS('مروة حسان'!$B$35:$B$70, $A20, 'مروة حسان'!$A$35:$A$70, $C$3, 'مروة حسان'!$G$35:$G$70, "تم الحل")+COUNTIFS('إيمان المبارك'!$B$35:$B$70, $A20, 'إيمان المبارك'!$A$35:$A$70, $C$3, 'إيمان المبارك'!$G$35:$G$70, "تم الحل")) -> 0 | F20: =IF($C$3="جميع الأسابيع", COUNTIFS('السيد سالم'!$B$35:$B$70, $A20, 'السيد سالم'!$G$35:$G$70, "مستمرة")+COUNTIFS('محمد السويركي'!$B$35:$B$70, $A20, 'محمد السويركي'!$G$35:$G$70, "مستمرة")+COUNTIFS('خالد عبد ربه'!$B$35:$B$70, $A20, 'خالد عبد ربه'!$G$35:$G$70, "مستمرة")+COUNTIFS('ناريمان الحجاجرة'!$B$35:$B$70, $A20, 'ناريمان الحجاجرة'!$G$35:$G$70, "مستمرة")+COUNTIFS('مروة حسان'!$B$35:$B$70, $A20, 'مروة حسان'!$G$35:$G$70, "مستمرة")+COUNTIFS('إيمان المبارك'!$B$35:$B$70, $A20, 'إيمان المبارك'!$G$35:$G$70, "مستمرة"), COUNTIFS('السيد سالم'!$B$35:$B$70, $A20, 'السيد سالم'!$A$35:$A$70, $C$3, 'السيد سالم'!$G$35:$G$70, "مستمرة")+COUNTIFS('محمد السويركي'!$B$35:$B$70, $A20, 'محمد السويركي'!$A$35:$A$70, $C$3, 'محمد السويركي'!$G$35:$G$70, "مستمرة")+COUNTIFS('خالد عبد ربه'!$B$35:$B$70, $A20, 'خالد عبد ربه'!$A$35:$A$70, $C$3, 'خالد عبد ربه'!$G$35:$G$70, "مستمرة")+COUNTIFS('ناريمان الحجاجرة'!$B$35:$B$70, $A20, 'ناريمان الحجاجرة'!$A$35:$A$70, $C$3, 'ناريمان الحجاجرة'!$G$35:$G$70, "مستمرة")+COUNTIFS('مروة حسان'!$B$35:$B$70, $A20, 'مروة حسان'!$A$35:$A$70, $C$3, 'مروة حسان'!$G$35:$G$70, "مستمرة")+COUNTIFS('إيمان المبارك'!$B$35:$B$70, $A20, 'إيمان المبارك'!$A$35:$A$70, $C$3, 'إيمان المبارك'!$G$35:$G$70, "مستمرة")) -> 0 | G20: =IFERROR(E20/(E20+F20), 0) -> 0 | H20: =IF(D20=0, "لا توجد ملاحظات", IF(F20=0, "تم إغلاق الملاحظات", "يوجد ملاحظات مستمرة")) -> تم إغلاق الملاحظات
A21: رواد قرطبة | B21: =C21+D21 -> 11 | C21: =IF($C$3="جميع الأسابيع", COUNTIF('السيد سالم'!$C$13:$C$32, $A21)+COUNTIF('محمد السويركي'!$C$13:$C$32, $A21)+COUNTIF('خالد عبد ربه'!$C$13:$C$32, $A21)+COUNTIF('ناريمان الحجاجرة'!$C$13:$C$32, $A21)+COUNTIF('مروة حسان'!$C$13:$C$32, $A21)+COUNTIF('إيمان المبارك'!$C$13:$C$32, $A21), COUNTIFS('السيد سالم'!$C$13:$C$32, $A21, 'السيد سالم'!$A$13:$A$32, $C$3)+COUNTIFS('محمد السويركي'!$C$13:$C$32, $A21, 'محمد السويركي'!$A$13:$A$32, $C$3)+COUNTIFS('خالد عبد ربه'!$C$13:$C$32, $A21, 'خالد عبد ربه'!$A$13:$A$32, $C$3)+COUNTIFS('ناريمان الحجاجرة'!$C$13:$C$32, $A21, 'ناريمان الحجاجرة'!$A$13:$A$32, $C$3)+COUNTIFS('مروة حسان'!$C$13:$C$32, $A21, 'مروة حسان'!$A$13:$A$32, $C$3)+COUNTIFS('إيمان المبارك'!$C$13:$C$32, $A21, 'إيمان المبارك'!$A$13:$A$32, $C$3)) -> 10 | D21: =IF($C$3="جميع الأسابيع", COUNTIF('السيد سالم'!$B$35:$B$70, $A21)+COUNTIF('محمد السويركي'!$B$35:$B$70, $A21)+COUNTIF('خالد عبد ربه'!$B$35:$B$70, $A21)+COUNTIF('ناريمان الحجاجرة'!$B$35:$B$70, $A21)+COUNTIF('مروة حسان'!$B$35:$B$70, $A21)+COUNTIF('إيمان المبارك'!$B$35:$B$70, $A21), COUNTIFS('السيد سالم'!$B$35:$B$70, $A21, 'السيد سالم'!$A$35:$A$70, $C$3)+COUNTIFS('محمد السويركي'!$B$35:$B$70, $A21, 'محمد السويركي'!$A$35:$A$70, $C$3)+COUNTIFS('خالد عبد ربه'!$B$35:$B$70, $A21, 'خالد عبد ربه'!$A$35:$A$70, $C$3)+COUNTIFS('ناريمان الحجاجرة'!$B$35:$B$70, $A21, 'ناريمان الحجاجرة'!$A$35:$A$70, $C$3)+COUNTIFS('مروة حسان'!$B$35:$B$70, $A21, 'مروة حسان'!$A$35:$A$70, $C$3)+COUNTIFS('إيمان المبارك'!$B$35:$B$70, $A21, 'إيمان المبارك'!$A$35:$A$70, $C$3)) -> 1 | E21: =IF($C$3="جميع الأسابيع", COUNTIFS('السيد سالم'!$B$35:$B$70, $A21, 'السيد سالم'!$G$35:$G$70, "تم الحل")+COUNTIFS('محمد السويركي'!$B$35:$B$70, $A21, 'محمد السويركي'!$G$35:$G$70, "تم الحل")+COUNTIFS('خالد عبد ربه'!$B$35:$B$70, $A21, 'خالد عبد ربه'!$G$35:$G$70, "تم الحل")+COUNTIFS('ناريمان الحجاجرة'!$B$35:$B$70, $A21, 'ناريمان الحجاجرة'!$G$35:$G$70, "تم الحل")+COUNTIFS('مروة حسان'!$B$35:$B$70, $A21, 'مروة حسان'!$G$35:$G$70, "تم الحل")+COUNTIFS('إيمان المبارك'!$B$35:$B$70, $A21, 'إيمان المبارك'!$G$35:$G$70, "تم الحل"), COUNTIFS('السيد سالم'!$B$35:$B$70, $A21, 'السيد سالم'!$A$35:$A$70, $C$3, 'السيد سالم'!$G$35:$G$70, "تم الحل")+COUNTIFS('محمد السويركي'!$B$35:$B$70, $A21, 'محمد السويركي'!$A$35:$A$70, $C$3, 'محمد السويركي'!$G$35:$G$70, "تم الحل")+COUNTIFS('خالد عبد ربه'!$B$35:$B$70, $A21, 'خالد عبد ربه'!$A$35:$A$70, $C$3, 'خالد عبد ربه'!$G$35:$G$70, "تم الحل")+COUNTIFS('ناريمان الحجاجرة'!$B$35:$B$70, $A21, 'ناريمان الحجاجرة'!$A$35:$A$70, $C$3, 'ناريمان الحجاجرة'!$G$35:$G$70, "تم الحل")+COUNTIFS('مروة حسان'!$B$35:$B$70, $A21, 'مروة حسان'!$A$35:$A$70, $C$3, 'مروة حسان'!$G$35:$G$70, "تم الحل")+COUNTIFS('إيمان المبارك'!$B$35:$B$70, $A21, 'إيمان المبارك'!$A$35:$A$70, $C$3, 'إيمان المبارك'!$G$35:$G$70, "تم الحل")) -> 0 | F21: =IF($C$3="جميع الأسابيع", COUNTIFS('السيد سالم'!$B$35:$B$70, $A21, 'السيد سالم'!$G$35:$G$70, "مستمرة")+COUNTIFS('محمد السويركي'!$B$35:$B$70, $A21, 'محمد السويركي'!$G$35:$G$70, "مستمرة")+COUNTIFS('خالد عبد ربه'!$B$35:$B$70, $A21, 'خالد عبد ربه'!$G$35:$G$70, "مستمرة")+COUNTIFS('ناريمان الحجاجرة'!$B$35:$B$70, $A21, 'ناريمان الحجاجرة'!$G$35:$G$70, "مستمرة")+COUNTIFS('مروة حسان'!$B$35:$B$70, $A21, 'مروة حسان'!$G$35:$G$70, "مستمرة")+COUNTIFS('إيمان المبارك'!$B$35:$B$70, $A21, 'إيمان المبارك'!$G$35:$G$70, "مستمرة"), COUNTIFS('السيد سالم'!$B$35:$B$70, $A21, 'السيد سالم'!$A$35:$A$70, $C$3, 'السيد سالم'!$G$35:$G$70, "مستمرة")+COUNTIFS('محمد السويركي'!$B$35:$B$70, $A21, 'محمد السويركي'!$A$35:$A$70, $C$3, 'محمد السويركي'!$G$35:$G$70, "مستمرة")+COUNTIFS('خالد عبد ربه'!$B$35:$B$70, $A21, 'خالد عبد ربه'!$A$35:$A$70, $C$3, 'خالد عبد ربه'!$G$35:$G$70, "مستمرة")+COUNTIFS('ناريمان الحجاجرة'!$B$35:$B$70, $A21, 'ناريمان الحجاجرة'!$A$35:$A$70, $C$3, 'ناريمان الحجاجرة'!$G$35:$G$70, "مستمرة")+COUNTIFS('مروة حسان'!$B$35:$B$70, $A21, 'مروة حسان'!$A$35:$A$70, $C$3, 'مروة حسان'!$G$35:$G$70, "مستمرة")+COUNTIFS('إيمان المبارك'!$B$35:$B$70, $A21, 'إيمان المبارك'!$A$35:$A$70, $C$3, 'إيمان المبارك'!$G$35:$G$70, "مستمرة")) -> 0 | G21: =IFERROR(E21/(E21+F21), 0) -> 0 | H21: =IF(D21=0, "لا توجد ملاحظات", IF(F21=0, "تم إغلاق الملاحظات", "يوجد ملاحظات مستمرة")) -> تم إغلاق الملاحظات
A22: رواد الروابي | B22: =C22+D22 -> 11 | C22: =IF($C$3="جميع الأسابيع", COUNTIF('السيد سالم'!$C$13:$C$32, $A22)+COUNTIF('محمد السويركي'!$C$13:$C$32, $A22)+COUNTIF('خالد عبد ربه'!$C$13:$C$32, $A22)+COUNTIF('ناريمان الحجاجرة'!$C$13:$C$32, $A22)+COUNTIF('مروة حسان'!$C$13:$C$32, $A22)+COUNTIF('إيمان المبارك'!$C$13:$C$32, $A22), COUNTIFS('السيد سالم'!$C$13:$C$32, $A22, 'السيد سالم'!$A$13:$A$32, $C$3)+COUNTIFS('محمد السويركي'!$C$13:$C$32, $A22, 'محمد السويركي'!$A$13:$A$32, $C$3)+COUNTIFS('خالد عبد ربه'!$C$13:$C$32, $A22, 'خالد عبد ربه'!$A$13:$A$32, $C$3)+COUNTIFS('ناريمان الحجاجرة'!$C$13:$C$32, $A22, 'ناريمان الحجاجرة'!$A$13:$A$32, $C$3)+COUNTIFS('مروة حسان'!$C$13:$C$32, $A22, 'مروة حسان'!$A$13:$A$32, $C$3)+COUNTIFS('إيمان المبارك'!$C$13:$C$32, $A22, 'إيمان المبارك'!$A$13:$A$32, $C$3)) -> 6 | D22: =IF($C$3="جميع الأسابيع", COUNTIF('السيد سالم'!$B$35:$B$70, $A22)+COUNTIF('محمد السويركي'!$B$35:$B$70, $A22)+COUNTIF('خالد عبد ربه'!$B$35:$B$70, $A22)+COUNTIF('ناريمان الحجاجرة'!$B$35:$B$70, $A22)+COUNTIF('مروة حسان'!$B$35:$B$70, $A22)+COUNTIF('إيمان المبارك'!$B$35:$B$70, $A22), COUNTIFS('السيد سالم'!$B$35:$B$70, $A22, 'السيد سالم'!$A$35:$A$70, $C$3)+COUNTIFS('محمد السويركي'!$B$35:$B$70, $A22, 'محمد السويركي'!$A$35:$A$70, $C$3)+COUNTIFS('خالد عبد ربه'!$B$35:$B$70, $A22, 'خالد عبد ربه'!$A$35:$A$70, $C$3)+COUNTIFS('ناريمان الحجاجرة'!$B$35:$B$70, $A22, 'ناريمان الحجاجرة'!$A$35:$A$70, $C$3)+COUNTIFS('مروة حسان'!$B$35:$B$70, $A22, 'مروة حسان'!$A$35:$A$70, $C$3)+COUNTIFS('إيمان المبارك'!$B$35:$B$70, $A22, 'إيمان المبارك'!$A$35:$A$70, $C$3)) -> 5 | E22: =IF($C$3="جميع الأسابيع", COUNTIFS('السيد سالم'!$B$35:$B$70, $A22, 'السيد سالم'!$G$35:$G$70, "تم الحل")+COUNTIFS('محمد السويركي'!$B$35:$B$70, $A22, 'محمد السويركي'!$G$35:$G$70, "تم الحل")+COUNTIFS('خالد عبد ربه'!$B$35:$B$70, $A22, 'خالد عبد ربه'!$G$35:$G$70, "تم الحل")+COUNTIFS('ناريمان الحجاجرة'!$B$35:$B$70, $A22, 'ناريمان الحجاجرة'!$G$35:$G$70, "تم الحل")+COUNTIFS('مروة حسان'!$B$35:$B$70, $A22, 'مروة حسان'!$G$35:$G$70, "تم الحل")+COUNTIFS('إيمان المبارك'!$B$35:$B$70, $A22, 'إيمان المبارك'!$G$35:$G$70, "تم الحل"), COUNTIFS('السيد سالم'!$B$35:$B$70, $A22, 'السيد سالم'!$A$35:$A$70, $C$3, 'السيد سالم'!$G$35:$G$70, "تم الحل")+COUNTIFS('محمد السويركي'!$B$35:$B$70, $A22, 'محمد السويركي'!$A$35:$A$70, $C$3, 'محمد السويركي'!$G$35:$G$70, "تم الحل")+COUNTIFS('خالد عبد ربه'!$B$35:$B$70, $A22, 'خالد عبد ربه'!$A$35:$A$70, $C$3, 'خالد عبد ربه'!$G$35:$G$70, "تم الحل")+COUNTIFS('ناريمان الحجاجرة'!$B$35:$B$70, $A22, 'ناريمان الحجاجرة'!$A$35:$A$70, $C$3, 'ناريمان الحجاجرة'!$G$35:$G$70, "تم الحل")+COUNTIFS('مروة حسان'!$B$35:$B$70, $A22, 'مروة حسان'!$A$35:$A$70, $C$3, 'مروة حسان'!$G$35:$G$70, "تم الحل")+COUNTIFS('إيمان المبارك'!$B$35:$B$70, $A22, 'إيمان المبارك'!$A$35:$A$70, $C$3, 'إيمان المبارك'!$G$35:$G$70, "تم الحل")) -> 5 | F22: =IF($C$3="جميع الأسابيع", COUNTIFS('السيد سالم'!$B$35:$B$70, $A22, 'السيد سالم'!$G$35:$G$70, "مستمرة")+COUNTIFS('محمد السويركي'!$B$35:$B$70, $A22, 'محمد السويركي'!$G$35:$G$70, "مستمرة")+COUNTIFS('خالد عبد ربه'!$B$35:$B$70, $A22, 'خالد عبد ربه'!$G$35:$G$70, "مستمرة")+COUNTIFS('ناريمان الحجاجرة'!$B$35:$B$70, $A22, 'ناريمان الحجاجرة'!$G$35:$G$70, "مستمرة")+COUNTIFS('مروة حسان'!$B$35:$B$70, $A22, 'مروة حسان'!$G$35:$G$70, "مستمرة")+COUNTIFS('إيمان المبارك'!$B$35:$B$70, $A22, 'إيمان المبارك'!$G$35:$G$70, "مستمرة"), COUNTIFS('السيد سالم'!$B$35:$B$70, $A22, 'السيد سالم'!$A$35:$A$70, $C$3, 'السيد سالم'!$G$35:$G$70, "مستمرة")+COUNTIFS('محمد السويركي'!$B$35:$B$70, $A22, 'محمد السويركي'!$A$35:$A$70, $C$3, 'محمد السويركي'!$G$35:$G$70, "مستمرة")+COUNTIFS('خالد عبد ربه'!$B$35:$B$70, $A22, 'خالد عبد ربه'!$A$35:$A$70, $C$3, 'خالد عبد ربه'!$G$35:$G$70, "مستمرة")+COUNTIFS('ناريمان الحجاجرة'!$B$35:$B$70, $A22, 'ناريمان الحجاجرة'!$A$35:$A$70, $C$3, 'ناريمان الحجاجرة'!$G$35:$G$70, "مستمرة")+COUNTIFS('مروة حسان'!$B$35:$B$70, $A22, 'مروة حسان'!$A$35:$A$70, $C$3, 'مروة حسان'!$G$35:$G$70, "مستمرة")+COUNTIFS('إيمان المبارك'!$B$35:$B$70, $A22, 'إيمان المبارك'!$A$35:$A$70, $C$3, 'إيمان المبارك'!$G$35:$G$70, "مستمرة")) -> 0 | G22: =IFERROR(E22/(E22+F22), 0) -> 1 | H22: =IF(D22=0, "لا توجد ملاحظات", IF(F22=0, "تم إغلاق الملاحظات", "يوجد ملاحظات مستمرة")) -> تم إغلاق الملاحظات
A23: رواد المنصورة | B23: =C23+D23 -> 8 | C23: =IF($C$3="جميع الأسابيع", COUNTIF('السيد سالم'!$C$13:$C$32, $A23)+COUNTIF('محمد السويركي'!$C$13:$C$32, $A23)+COUNTIF('خالد عبد ربه'!$C$13:$C$32, $A23)+COUNTIF('ناريمان الحجاجرة'!$C$13:$C$32, $A23)+COUNTIF('مروة حسان'!$C$13:$C$32, $A23)+COUNTIF('إيمان المبارك'!$C$13:$C$32, $A23), COUNTIFS('السيد سالم'!$C$13:$C$32, $A23, 'السيد سالم'!$A$13:$A$32, $C$3)+COUNTIFS('محمد السويركي'!$C$13:$C$32, $A23, 'محمد السويركي'!$A$13:$A$32, $C$3)+COUNTIFS('خالد عبد ربه'!$C$13:$C$32, $A23, 'خالد عبد ربه'!$A$13:$A$32, $C$3)+COUNTIFS('ناريمان الحجاجرة'!$C$13:$C$32, $A23, 'ناريمان الحجاجرة'!$A$13:$A$32, $C$3)+COUNTIFS('مروة حسان'!$C$13:$C$32, $A23, 'مروة حسان'!$A$13:$A$32, $C$3)+COUNTIFS('إيمان المبارك'!$C$13:$C$32, $A23, 'إيمان المبارك'!$A$13:$A$32, $C$3)) -> 6 | D23: =IF($C$3="جميع الأسابيع", COUNTIF('السيد سالم'!$B$35:$B$70, $A23)+COUNTIF('محمد السويركي'!$B$35:$B$70, $A23)+COUNTIF('خالد عبد ربه'!$B$35:$B$70, $A23)+COUNTIF('ناريمان الحجاجرة'!$B$35:$B$70, $A23)+COUNTIF('مروة حسان'!$B$35:$B$70, $A23)+COUNTIF('إيمان المبارك'!$B$35:$B$70, $A23), COUNTIFS('السيد سالم'!$B$35:$B$70, $A23, 'السيد سالم'!$A$35:$A$70, $C$3)+COUNTIFS('محمد السويركي'!$B$35:$B$70, $A23, 'محمد السويركي'!$A$35:$A$70, $C$3)+COUNTIFS('خالد عبد ربه'!$B$35:$B$70, $A23, 'خالد عبد ربه'!$A$35:$A$70, $C$3)+COUNTIFS('ناريمان الحجاجرة'!$B$35:$B$70, $A23, 'ناريمان الحجاجرة'!$A$35:$A$70, $C$3)+COUNTIFS('مروة حسان'!$B$35:$B$70, $A23, 'مروة حسان'!$A$35:$A$70, $C$3)+COUNTIFS('إيمان المبارك'!$B$35:$B$70, $A23, 'إيمان المبارك'!$A$35:$A$70, $C$3)) -> 2 | E23: =IF($C$3="جميع الأسابيع", COUNTIFS('السيد سالم'!$B$35:$B$70, $A23, 'السيد سالم'!$G$35:$G$70, "تم الحل")+COUNTIFS('محمد السويركي'!$B$35:$B$70, $A23, 'محمد السويركي'!$G$35:$G$70, "تم الحل")+COUNTIFS('خالد عبد ربه'!$B$35:$B$70, $A23, 'خالد عبد ربه'!$G$35:$G$70, "تم الحل")+COUNTIFS('ناريمان الحجاجرة'!$B$35:$B$70, $A23, 'ناريمان الحجاجرة'!$G$35:$G$70, "تم الحل")+COUNTIFS('مروة حسان'!$B$35:$B$70, $A23, 'مروة حسان'!$G$35:$G$70, "تم الحل")+COUNTIFS('إيمان المبارك'!$B$35:$B$70, $A23, 'إيمان المبارك'!$G$35:$G$70, "تم الحل"), COUNTIFS('السيد سالم'!$B$35:$B$70, $A23, 'السيد سالم'!$A$35:$A$70, $C$3, 'السيد سالم'!$G$35:$G$70, "تم الحل")+COUNTIFS('محمد السويركي'!$B$35:$B$70, $A23, 'محمد السويركي'!$A$35:$A$70, $C$3, 'محمد السويركي'!$G$35:$G$70, "تم الحل")+COUNTIFS('خالد عبد ربه'!$B$35:$B$70, $A23, 'خالد عبد ربه'!$A$35:$A$70, $C$3, 'خالد عبد ربه'!$G$35:$G$70, "تم الحل")+COUNTIFS('ناريمان الحجاجرة'!$B$35:$B$70, $A23, 'ناريمان الحجاجرة'!$A$35:$A$70, $C$3, 'ناريمان الحجاجرة'!$G$35:$G$70, "تم الحل")+COUNTIFS('مروة حسان'!$B$35:$B$70, $A23, 'مروة حسان'!$A$35:$A$70, $C$3, 'مروة حسان'!$G$35:$G$70, "تم الحل")+COUNTIFS('إيمان المبارك'!$B$35:$B$70, $A23, 'إيمان المبارك'!$A$35:$A$70, $C$3, 'إيمان المبارك'!$G$35:$G$70, "تم الحل")) -> 2 | F23: =IF($C$3="جميع الأسابيع", COUNTIFS('السيد سالم'!$B$35:$B$70, $A23, 'السيد سالم'!$G$35:$G$70, "مستمرة")+COUNTIFS('محمد السويركي'!$B$35:$B$70, $A23, 'محمد السويركي'!$G$35:$G$70, "مستمرة")+COUNTIFS('خالد عبد ربه'!$B$35:$B$70, $A23, 'خالد عبد ربه'!$G$35:$G$70, "مستمرة")+COUNTIFS('ناريمان الحجاجرة'!$B$35:$B$70, $A23, 'ناريمان الحجاجرة'!$G$35:$G$70, "مستمرة")+COUNTIFS('مروة حسان'!$B$35:$B$70, $A23, 'مروة حسان'!$G$35:$G$70, "مستمرة")+COUNTIFS('إيمان المبارك'!$B$35:$B$70, $A23, 'إيمان المبارك'!$G$35:$G$70, "مستمرة"), COUNTIFS('السيد سالم'!$B$35:$B$70, $A23, 'السيد سالم'!$A$35:$A$70, $C$3, 'السيد سالم'!$G$35:$G$70, "مستمرة")+COUNTIFS('محمد السويركي'!$B$35:$B$70, $A23, 'محمد السويركي'!$A$35:$A$70, $C$3, 'محمد السويركي'!$G$35:$G$70, "مستمرة")+COUNTIFS('خالد عبد ربه'!$B$35:$B$70, $A23, 'خالد عبد ربه'!$A$35:$A$70, $C$3, 'خالد عبد ربه'!$G$35:$G$70, "مستمرة")+COUNTIFS('ناريمان الحجاجرة'!$B$35:$B$70, $A23, 'ناريمان الحجاجرة'!$A$35:$A$70, $C$3, 'ناريمان الحجاجرة'!$G$35:$G$70, "مستمرة")+COUNTIFS('مروة حسان'!$B$35:$B$70, $A23, 'مروة حسان'!$A$35:$A$70, $C$3, 'مروة حسان'!$G$35:$G$70, "مستمرة")+COUNTIFS('إيمان المبارك'!$B$35:$B$70, $A23, 'إيمان المبارك'!$A$35:$A$70, $C$3, 'إيمان المبارك'!$G$35:$G$70, "مستمرة")) -> 0 | G23: =IFERROR(E23/(E23+F23), 0) -> 1 | H23: =IF(D23=0, "لا توجد ملاحظات", IF(F23=0, "تم إغلاق الملاحظات", "يوجد ملاحظات مستمرة")) -> تم إغلاق الملاحظات
A24: النخبة -الخرج | B24: =C24+D24 -> 0 | C24: =IF($C$3="جميع الأسابيع", COUNTIF('السيد سالم'!$C$13:$C$32, $A24)+COUNTIF('محمد السويركي'!$C$13:$C$32, $A24)+COUNTIF('خالد عبد ربه'!$C$13:$C$32, $A24)+COUNTIF('ناريمان الحجاجرة'!$C$13:$C$32, $A24)+COUNTIF('مروة حسان'!$C$13:$C$32, $A24)+COUNTIF('إيمان المبارك'!$C$13:$C$32, $A24), COUNTIFS('السيد سالم'!$C$13:$C$32, $A24, 'السيد سالم'!$A$13:$A$32, $C$3)+COUNTIFS('محمد السويركي'!$C$13:$C$32, $A24, 'محمد السويركي'!$A$13:$A$32, $C$3)+COUNTIFS('خالد عبد ربه'!$C$13:$C$32, $A24, 'خالد عبد ربه'!$A$13:$A$32, $C$3)+COUNTIFS('ناريمان الحجاجرة'!$C$13:$C$32, $A24, 'ناريمان الحجاجرة'!$A$13:$A$32, $C$3)+COUNTIFS('مروة حسان'!$C$13:$C$32, $A24, 'مروة حسان'!$A$13:$A$32, $C$3)+COUNTIFS('إيمان المبارك'!$C$13:$C$32, $A24, 'إيمان المبارك'!$A$13:$A$32, $C$3)) -> 0 | D24: =IF($C$3="جميع الأسابيع", COUNTIF('السيد سالم'!$B$35:$B$70, $A24)+COUNTIF('محمد السويركي'!$B$35:$B$70, $A24)+COUNTIF('خالد عبد ربه'!$B$35:$B$70, $A24)+COUNTIF('ناريمان الحجاجرة'!$B$35:$B$70, $A24)+COUNTIF('مروة حسان'!$B$35:$B$70, $A24)+COUNTIF('إيمان المبارك'!$B$35:$B$70, $A24), COUNTIFS('السيد سالم'!$B$35:$B$70, $A24, 'السيد سالم'!$A$35:$A$70, $C$3)+COUNTIFS('محمد السويركي'!$B$35:$B$70, $A24, 'محمد السويركي'!$A$35:$A$70, $C$3)+COUNTIFS('خالد عبد ربه'!$B$35:$B$70, $A24, 'خالد عبد ربه'!$A$35:$A$70, $C$3)+COUNTIFS('ناريمان الحجاجرة'!$B$35:$B$70, $A24, 'ناريمان الحجاجرة'!$A$35:$A$70, $C$3)+COUNTIFS('مروة حسان'!$B$35:$B$70, $A24, 'مروة حسان'!$A$35:$A$70, $C$3)+COUNTIFS('إيمان المبارك'!$B$35:$B$70, $A24, 'إيمان المبارك'!$A$35:$A$70, $C$3)) -> 0 | E24: =IF($C$3="جميع الأسابيع", COUNTIFS('السيد سالم'!$B$35:$B$70, $A24, 'السيد سالم'!$G$35:$G$70, "تم الحل")+COUNTIFS('محمد السويركي'!$B$35:$B$70, $A24, 'محمد السويركي'!$G$35:$G$70, "تم الحل")+COUNTIFS('خالد عبد ربه'!$B$35:$B$70, $A24, 'خالد عبد ربه'!$G$35:$G$70, "تم الحل")+COUNTIFS('ناريمان الحجاجرة'!$B$35:$B$70, $A24, 'ناريمان الحجاجرة'!$G$35:$G$70, "تم الحل")+COUNTIFS('مروة حسان'!$B$35:$B$70, $A24, 'مروة حسان'!$G$35:$G$70, "تم الحل")+COUNTIFS('إيمان المبارك'!$B$35:$B$70, $A24, 'إيمان المبارك'!$G$35:$G$70, "تم الحل"), COUNTIFS('السيد سالم'!$B$35:$B$70, $A24, 'السيد سالم'!$A$35:$A$70, $C$3, 'السيد سالم'!$G$35:$G$70, "تم الحل")+COUNTIFS('محمد السويركي'!$B$35:$B$70, $A24, 'محمد السويركي'!$A$35:$A$70, $C$3, 'محمد السويركي'!$G$35:$G$70, "تم الحل")+COUNTIFS('خالد عبد ربه'!$B$35:$B$70, $A24, 'خالد عبد ربه'!$A$35:$A$70, $C$3, 'خالد عبد ربه'!$G$35:$G$70, "تم الحل")+COUNTIFS('ناريمان الحجاجرة'!$B$35:$B$70, $A24, 'ناريمان الحجاجرة'!$A$35:$A$70, $C$3, 'ناريمان الحجاجرة'!$G$35:$G$70, "تم الحل")+COUNTIFS('مروة حسان'!$B$35:$B$70, $A24, 'مروة حسان'!$A$35:$A$70, $C$3, 'مروة حسان'!$G$35:$G$70, "تم الحل")+COUNTIFS('إيمان المبارك'!$B$35:$B$70, $A24, 'إيمان المبارك'!$A$35:$A$70, $C$3, 'إيمان المبارك'!$G$35:$G$70, "تم الحل")) -> 0 | F24: =IF($C$3="جميع الأسابيع", COUNTIFS('السيد سالم'!$B$35:$B$70, $A24, 'السيد سالم'!$G$35:$G$70, "مستمرة")+COUNTIFS('محمد السويركي'!$B$35:$B$70, $A24, 'محمد السويركي'!$G$35:$G$70, "مستمرة")+COUNTIFS('خالد عبد ربه'!$B$35:$B$70, $A24, 'خالد عبد ربه'!$G$35:$G$70, "مستمرة")+COUNTIFS('ناريمان الحجاجرة'!$B$35:$B$70, $A24, 'ناريمان الحجاجرة'!$G$35:$G$70, "مستمرة")+COUNTIFS('مروة حسان'!$B$35:$B$70, $A24, 'مروة حسان'!$G$35:$G$70, "مستمرة")+COUNTIFS('إيمان المبارك'!$B$35:$B$70, $A24, 'إيمان المبارك'!$G$35:$G$70, "مستمرة"), COUNTIFS('السيد سالم'!$B$35:$B$70, $A24, 'السيد سالم'!$A$35:$A$70, $C$3, 'السيد سالم'!$G$35:$G$70, "مستمرة")+COUNTIFS('محمد السويركي'!$B$35:$B$70, $A24, 'محمد السويركي'!$A$35:$A$70, $C$3, 'محمد السويركي'!$G$35:$G$70, "مستمرة")+COUNTIFS('خالد عبد ربه'!$B$35:$B$70, $A24, 'خالد عبد ربه'!$A$35:$A$70, $C$3, 'خالد عبد ربه'!$G$35:$G$70, "مستمرة")+COUNTIFS('ناريمان الحجاجرة'!$B$35:$B$70, $A24, 'ناريمان الحجاجرة'!$A$35:$A$70, $C$3, 'ناريمان الحجاجرة'!$G$35:$G$70, "مستمرة")+COUNTIFS('مروة حسان'!$B$35:$B$70, $A24, 'مروة حسان'!$A$35:$A$70, $C$3, 'مروة حسان'!$G$35:$G$70, "مستمرة")+COUNTIFS('إيمان المبارك'!$B$35:$B$70, $A24, 'إيمان المبارك'!$A$35:$A$70, $C$3, 'إيمان المبارك'!$G$35:$G$70, "مستمرة")) -> 0 | G24: =IFERROR(E24/(E24+F24), 0) -> 0 | H24: =IF(D24=0, "لا توجد ملاحظات", IF(F24=0, "تم إغلاق الملاحظات", "يوجد ملاحظات مستمرة")) -> لا توجد ملاحظات
A25: الوسط | B25: =C25+D25 -> 4 | C25: =IF($C$3="جميع الأسابيع", COUNTIF('السيد سالم'!$C$13:$C$32, $A25)+COUNTIF('محمد السويركي'!$C$13:$C$32, $A25)+COUNTIF('خالد عبد ربه'!$C$13:$C$32, $A25)+COUNTIF('ناريمان الحجاجرة'!$C$13:$C$32, $A25)+COUNTIF('مروة حسان'!$C$13:$C$32, $A25)+COUNTIF('إيمان المبارك'!$C$13:$C$32, $A25), COUNTIFS('السيد سالم'!$C$13:$C$32, $A25, 'السيد سالم'!$A$13:$A$32, $C$3)+COUNTIFS('محمد السويركي'!$C$13:$C$32, $A25, 'محمد السويركي'!$A$13:$A$32, $C$3)+COUNTIFS('خالد عبد ربه'!$C$13:$C$32, $A25, 'خالد عبد ربه'!$A$13:$A$32, $C$3)+COUNTIFS('ناريمان الحجاجرة'!$C$13:$C$32, $A25, 'ناريمان الحجاجرة'!$A$13:$A$32, $C$3)+COUNTIFS('مروة حسان'!$C$13:$C$32, $A25, 'مروة حسان'!$A$13:$A$32, $C$3)+COUNTIFS('إيمان المبارك'!$C$13:$C$32, $A25, 'إيمان المبارك'!$A$13:$A$32, $C$3)) -> 3 | D25: =IF($C$3="جميع الأسابيع", COUNTIF('السيد سالم'!$B$35:$B$70, $A25)+COUNTIF('محمد السويركي'!$B$35:$B$70, $A25)+COUNTIF('خالد عبد ربه'!$B$35:$B$70, $A25)+COUNTIF('ناريمان الحجاجرة'!$B$35:$B$70, $A25)+COUNTIF('مروة حسان'!$B$35:$B$70, $A25)+COUNTIF('إيمان المبارك'!$B$35:$B$70, $A25), COUNTIFS('السيد سالم'!$B$35:$B$70, $A25, 'السيد سالم'!$A$35:$A$70, $C$3)+COUNTIFS('محمد السويركي'!$B$35:$B$70, $A25, 'محمد السويركي'!$A$35:$A$70, $C$3)+COUNTIFS('خالد عبد ربه'!$B$35:$B$70, $A25, 'خالد عبد ربه'!$A$35:$A$70, $C$3)+COUNTIFS('ناريمان الحجاجرة'!$B$35:$B$70, $A25, 'ناريمان الحجاجرة'!$A$35:$A$70, $C$3)+COUNTIFS('مروة حسان'!$B$35:$B$70, $A25, 'مروة حسان'!$A$35:$A$70, $C$3)+COUNTIFS('إيمان المبارك'!$B$35:$B$70, $A25, 'إيمان المبارك'!$A$35:$A$70, $C$3)) -> 1 | E25: =IF($C$3="جميع الأسابيع", COUNTIFS('السيد سالم'!$B$35:$B$70, $A25, 'السيد سالم'!$G$35:$G$70, "تم الحل")+COUNTIFS('محمد السويركي'!$B$35:$B$70, $A25, 'محمد السويركي'!$G$35:$G$70, "تم الحل")+COUNTIFS('خالد عبد ربه'!$B$35:$B$70, $A25, 'خالد عبد ربه'!$G$35:$G$70, "تم الحل")+COUNTIFS('ناريمان الحجاجرة'!$B$35:$B$70, $A25, 'ناريمان الحجاجرة'!$G$35:$G$70, "تم الحل")+COUNTIFS('مروة حسان'!$B$35:$B$70, $A25, 'مروة حسان'!$G$35:$G$70, "تم الحل")+COUNTIFS('إيمان المبارك'!$B$35:$B$70, $A25, 'إيمان المبارك'!$G$35:$G$70, "تم الحل"), COUNTIFS('السيد سالم'!$B$35:$B$70, $A25, 'السيد سالم'!$A$35:$A$70, $C$3, 'السيد سالم'!$G$35:$G$70, "تم الحل")+COUNTIFS('محمد السويركي'!$B$35:$B$70, $A25, 'محمد السويركي'!$A$35:$A$70, $C$3, 'محمد السويركي'!$G$35:$G$70, "تم الحل")+COUNTIFS('خالد عبد ربه'!$B$35:$B$70, $A25, 'خالد عبد ربه'!$A$35:$A$70, $C$3, 'خالد عبد ربه'!$G$35:$G$70, "تم الحل")+COUNTIFS('ناريمان الحجاجرة'!$B$35:$B$70, $A25, 'ناريمان الحجاجرة'!$A$35:$A$70, $C$3, 'ناريمان الحجاجرة'!$G$35:$G$70, "تم الحل")+COUNTIFS('مروة حسان'!$B$35:$B$70, $A25, 'مروة حسان'!$A$35:$A$70, $C$3, 'مروة حسان'!$G$35:$G$70, "تم الحل")+COUNTIFS('إيمان المبارك'!$B$35:$B$70, $A25, 'إيمان المبارك'!$A$35:$A$70, $C$3, 'إيمان المبارك'!$G$35:$G$70, "تم الحل")) -> 1 | F25: =IF($C$3="جميع الأسابيع", COUNTIFS('السيد سالم'!$B$35:$B$70, $A25, 'السيد سالم'!$G$35:$G$70, "مستمرة")+COUNTIFS('محمد السويركي'!$B$35:$B$70, $A25, 'محمد السويركي'!$G$35:$G$70, "مستمرة")+COUNTIFS('خالد عبد ربه'!$B$35:$B$70, $A25, 'خالد عبد ربه'!$G$35:$G$70, "مستمرة")+COUNTIFS('ناريمان الحجاجرة'!$B$35:$B$70, $A25, 'ناريمان الحجاجرة'!$G$35:$G$70, "مستمرة")+COUNTIFS('مروة حسان'!$B$35:$B$70, $A25, 'مروة حسان'!$G$35:$G$70, "مستمرة")+COUNTIFS('إيمان المبارك'!$B$35:$B$70, $A25, 'إيمان المبارك'!$G$35:$G$70, "مستمرة"), COUNTIFS('السيد سالم'!$B$35:$B$70, $A25, 'السيد سالم'!$A$35:$A$70, $C$3, 'السيد سالم'!$G$35:$G$70, "مستمرة")+COUNTIFS('محمد السويركي'!$B$35:$B$70, $A25, 'محمد السويركي'!$A$35:$A$70, $C$3, 'محمد السويركي'!$G$35:$G$70, "مستمرة")+COUNTIFS('خالد عبد ربه'!$B$35:$B$70, $A25, 'خالد عبد ربه'!$A$35:$A$70, $C$3, 'خالد عبد ربه'!$G$35:$G$70, "مستمرة")+COUNTIFS('ناريمان الحجاجرة'!$B$35:$B$70, $A25, 'ناريمان الحجاجرة'!$A$35:$A$70, $C$3, 'ناريمان الحجاجرة'!$G$35:$G$70, "مستمرة")+COUNTIFS('مروة حسان'!$B$35:$B$70, $A25, 'مروة حسان'!$A$35:$A$70, $C$3, 'مروة حسان'!$G$35:$G$70, "مستمرة")+COUNTIFS('إيمان المبارك'!$B$35:$B$70, $A25, 'إيمان المبارك'!$A$35:$A$70, $C$3, 'إيمان المبارك'!$G$35:$G$70, "مستمرة")) -> 0 | G25: =IFERROR(E25/(E25+F25), 0) -> 1 | H25: =IF(D25=0, "لا توجد ملاحظات", IF(F25=0, "تم إغلاق الملاحظات", "يوجد ملاحظات مستمرة")) -> تم إغلاق الملاحظات
A26: الجودة | B26: =C26+D26 -> 0 | C26: =IF($C$3="جميع الأسابيع", COUNTIF('السيد سالم'!$C$13:$C$32, $A26)+COUNTIF('محمد السويركي'!$C$13:$C$32, $A26)+COUNTIF('خالد عبد ربه'!$C$13:$C$32, $A26)+COUNTIF('ناريمان الحجاجرة'!$C$13:$C$32, $A26)+COUNTIF('مروة حسان'!$C$13:$C$32, $A26)+COUNTIF('إيمان المبارك'!$C$13:$C$32, $A26), COUNTIFS('السيد سالم'!$C$13:$C$32, $A26, 'السيد سالم'!$A$13:$A$32, $C$3)+COUNTIFS('محمد السويركي'!$C$13:$C$32, $A26, 'محمد السويركي'!$A$13:$A$32, $C$3)+COUNTIFS('خالد عبد ربه'!$C$13:$C$32, $A26, 'خالد عبد ربه'!$A$13:$A$32, $C$3)+COUNTIFS('ناريمان الحجاجرة'!$C$13:$C$32, $A26, 'ناريمان الحجاجرة'!$A$13:$A$32, $C$3)+COUNTIFS('مروة حسان'!$C$13:$C$32, $A26, 'مروة حسان'!$A$13:$A$32, $C$3)+COUNTIFS('إيمان المبارك'!$C$13:$C$32, $A26, 'إيمان المبارك'!$A$13:$A$32, $C$3)) -> 0 | D26: =IF($C$3="جميع الأسابيع", COUNTIF('السيد سالم'!$B$35:$B$70, $A26)+COUNTIF('محمد السويركي'!$B$35:$B$70, $A26)+COUNTIF('خالد عبد ربه'!$B$35:$B$70, $A26)+COUNTIF('ناريمان الحجاجرة'!$B$35:$B$70, $A26)+COUNTIF('مروة حسان'!$B$35:$B$70, $A26)+COUNTIF('إيمان المبارك'!$B$35:$B$70, $A26), COUNTIFS('السيد سالم'!$B$35:$B$70, $A26, 'السيد سالم'!$A$35:$A$70, $C$3)+COUNTIFS('محمد السويركي'!$B$35:$B$70, $A26, 'محمد السويركي'!$A$35:$A$70, $C$3)+COUNTIFS('خالد عبد ربه'!$B$35:$B$70, $A26, 'خالد عبد ربه'!$A$35:$A$70, $C$3)+COUNTIFS('ناريمان الحجاجرة'!$B$35:$B$70, $A26, 'ناريمان الحجاجرة'!$A$35:$A$70, $C$3)+COUNTIFS('مروة حسان'!$B$35:$B$70, $A26, 'مروة حسان'!$A$35:$A$70, $C$3)+COUNTIFS('إيمان المبارك'!$B$35:$B$70, $A26, 'إيمان المبارك'!$A$35:$A$70, $C$3)) -> 0 | E26: =IF($C$3="جميع الأسابيع", COUNTIFS('السيد سالم'!$B$35:$B$70, $A26, 'السيد سالم'!$G$35:$G$70, "تم الحل")+COUNTIFS('محمد السويركي'!$B$35:$B$70, $A26, 'محمد السويركي'!$G$35:$G$70, "تم الحل")+COUNTIFS('خالد عبد ربه'!$B$35:$B$70, $A26, 'خالد عبد ربه'!$G$35:$G$70, "تم الحل")+COUNTIFS('ناريمان الحجاجرة'!$B$35:$B$70, $A26, 'ناريمان الحجاجرة'!$G$35:$G$70, "تم الحل")+COUNTIFS('مروة حسان'!$B$35:$B$70, $A26, 'مروة حسان'!$G$35:$G$70, "تم الحل")+COUNTIFS('إيمان المبارك'!$B$35:$B$70, $A26, 'إيمان المبارك'!$G$35:$G$70, "تم الحل"), COUNTIFS('السيد سالم'!$B$35:$B$70, $A26, 'السيد سالم'!$A$35:$A$70, $C$3, 'السيد سالم'!$G$35:$G$70, "تم الحل")+COUNTIFS('محمد السويركي'!$B$35:$B$70, $A26, 'محمد السويركي'!$A$35:$A$70, $C$3, 'محمد السويركي'!$G$35:$G$70, "تم الحل")+COUNTIFS('خالد عبد ربه'!$B$35:$B$70, $A26, 'خالد عبد ربه'!$A$35:$A$70, $C$3, 'خالد عبد ربه'!$G$35:$G$70, "تم الحل")+COUNTIFS('ناريمان الحجاجرة'!$B$35:$B$70, $A26, 'ناريمان الحجاجرة'!$A$35:$A$70, $C$3, 'ناريمان الحجاجرة'!$G$35:$G$70, "تم الحل")+COUNTIFS('مروة حسان'!$B$35:$B$70, $A26, 'مروة حسان'!$A$35:$A$70, $C$3, 'مروة حسان'!$G$35:$G$70, "تم الحل")+COUNTIFS('إيمان المبارك'!$B$35:$B$70, $A26, 'إيمان المبارك'!$A$35:$A$70, $C$3, 'إيمان المبارك'!$G$35:$G$70, "تم الحل")) -> 0 | F26: =IF($C$3="جميع الأسابيع", COUNTIFS('السيد سالم'!$B$35:$B$70, $A26, 'السيد سالم'!$G$35:$G$70, "مستمرة")+COUNTIFS('محمد السويركي'!$B$35:$B$70, $A26, 'محمد السويركي'!$G$35:$G$70, "مستمرة")+COUNTIFS('خالد عبد ربه'!$B$35:$B$70, $A26, 'خالد عبد ربه'!$G$35:$G$70, "مستمرة")+COUNTIFS('ناريمان الحجاجرة'!$B$35:$B$70, $A26, 'ناريمان الحجاجرة'!$G$35:$G$70, "مستمرة")+COUNTIFS('مروة حسان'!$B$35:$B$70, $A26, 'مروة حسان'!$G$35:$G$70, "مستمرة")+COUNTIFS('إيمان المبارك'!$B$35:$B$70, $A26, 'إيمان المبارك'!$G$35:$G$70, "مستمرة"), COUNTIFS('السيد سالم'!$B$35:$B$70, $A26, 'السيد سالم'!$A$35:$A$70, $C$3, 'السيد سالم'!$G$35:$G$70, "مستمرة")+COUNTIFS('محمد السويركي'!$B$35:$B$70, $A26, 'محمد السويركي'!$A$35:$A$70, $C$3, 'محمد السويركي'!$G$35:$G$70, "مستمرة")+COUNTIFS('خالد عبد ربه'!$B$35:$B$70, $A26, 'خالد عبد ربه'!$A$35:$A$70, $C$3, 'خالد عبد ربه'!$G$35:$G$70, "مستمرة")+COUNTIFS('ناريمان الحجاجرة'!$B$35:$B$70, $A26, 'ناريمان الحجاجرة'!$A$35:$A$70, $C$3, 'ناريمان الحجاجرة'!$G$35:$G$70, "مستمرة")+COUNTIFS('مروة حسان'!$B$35:$B$70, $A26, 'مروة حسان'!$A$35:$A$70, $C$3, 'مروة حسان'!$G$35:$G$70, "مستمرة")+COUNTIFS('إيمان المبارك'!$B$35:$B$70, $A26, 'إيمان المبارك'!$A$35:$A$70, $C$3, 'إيمان المبارك'!$G$35:$G$70, "مستمرة")) -> 0 | G26: =IFERROR(E26/(E26+F26), 0) -> 0 | H26: =IF(D26=0, "لا توجد ملاحظات", IF(F26=0, "تم إغلاق الملاحظات", "يوجد ملاحظات مستمرة")) -> لا توجد ملاحظات
A27: إجمالي المجمعات | B27: =SUM(B16:B26) -> 78 | C27: =SUM(C16:C26) -> 55 | D27: =SUM(D16:D26) -> 23 | E27: =SUM(E16:E26) -> 15 | F27: =SUM(F16:F26) -> 3 | G27: =IFERROR(E27/(E27+F27), 0) -> 0.83333333 | H27: -

Sheet قوائم_البيانات
A1: جميع الأسابيع | B1: جميع المجمعات | C1: ابتدائي
A2: الأسبوع 1 | B2: رواد الإزدهار | C2: متوسط
A3: الأسبوع 2 | B3: رواد الغدير | C3: ثانوي
A4: الأسبوع 3 | B4: رواد عرقة
A5: الأسبوع 4 | B5: رواد أشبيلية
A6: الأسبوع 5 | B6: رواد الأندلس
A7: الأسبوع 6 | B7: رواد قرطبة
A8: الأسبوع 7 | B8: رواد الروابي
A9: الأسبوع 8 | B9: رواد المنصورة
A10: الأسبوع 9 | B10: النخبة -الخرج
A11: الأسبوع 10 | B11: الوسط
A12: الأسبوع 11 | B12: الجودة
A13: الأسبوع 12
A14: الأسبوع 13
A15: الأسبوع 14
A16: الأسبوع 15
A17: الأسبوع 16
A18: الأسبوع 17

Sheet السيد سالم
A1: تقرير متابعة التعليم عن بعد - قسم الرياضيات - المشرف التربوي: السيد سالم
A2: المؤشرات الإجمالية للمشرف (الفصل الدراسي - 17 أسبوعاً) | D2: العدد / النسبة | E2: ملاحظات وتوجيهات الحساب التلقائي
A3: إجمالي عدد المعلمين (تميز / فرص تحسين) | D3: =COUNTA(B13:B32) + COUNTA(D35:D70) -> 19 | E3: تُحسب آلياً من لوحة التميز + سجل التطوير والملاحظات
A4: إجمالي المعلمين المتميزين | D4: =COUNTA(B13:B32) -> 11 | E4: تُحسب آلياً من لوحة المعلمين المتميزين
